Workbook

Sheet Final Summary
A2: TENDER NO. D-111808 CONSTRUCTION WORKS FOR REPLACEMENT OF SHBPRY, SMHPRY AND DRPRY SUBSTATION IN EASTERN REGION Lot 1: Shobaisi PRY (SHBPRY)
A4: Item No. | B4: DESCRIPTION | C4: Total Price (AED) | E4: Total Price (AED) A+B
C5: CIF / Local (AED) - A | D5: Erection (AED) - B
A6: 1 | B6: ='[1]Items 1,2,3-Construction Works'!B213 -> Electrical Works for new 33/11 kV Primary Substation | C6: =+'Items 1,2,3-Construction Works'!F213 -> 23787066 | D6: =+'Items 1,2,3-Construction Works'!H213 -> 4573689 | E6: =C6+D6 -> 28360755
A7: 2 | B7: ='[1]Items 1,2,3-Construction Works'!B214 -> Mechanical Works for new 33/11 kV Primary Substation | C7: =+'Items 1,2,3-Construction Works'!F214 -> 4554179.9 | D7: =+'Items 1,2,3-Construction Works'!H214 -> 1043644.8 | E7: =C7+D7 -> 5597824.6
A8: 3 | B8: ='[1]Items 1,2,3-Construction Works'!B215 -> Civil Works for new 33/11 kV Primary Substation Building | C8: =+'Items 1,2,3-Construction Works'!F215 -> 0 | D8: =+'Items 1,2,3-Construction Works'!H215 -> 16229500 | E8: =C8+D8 -> 16229500
A9: 4 | B9: ='[1]Items 4-Load Diversion Works'!B71 -> Interconnecting Cables between Grid Station and the new Primary Substation and Load Diversion works | C9: =+'Items 4-Load Diversion Works'!F73 -> 0 | D9: =+'Items 4-Load Diversion Works'!H73 -> 1389385.8 | E9: =C9+D9 -> 1389385.8
A10: 5 | B10: ='[1]Items 5-8 Dismantl & Modif work'!B21 -> Dismantling, Decommissioning & Demolition Works of existing old 33/11kV primary substation (SHBPRY) | C10: =+'Items 5-8 Dismantl & Modif work'!F21 -> 0 | D10: =+'Items 5-8 Dismantl & Modif work'!H21 -> 193226.5 | E10: =C10+D10 -> 193226.5
A11: 6 | B11: ='[1]Items 5-8 Dismantl & Modif work'!B22 -> Dismantling & Decommissioning Works of old 2 nos. Package Units (SHBPRY2 & SHBPRY3) | C11: =+'Items 5-8 Dismantl & Modif work'!F22 -> 0 | D11: =+'Items 5-8 Dismantl & Modif work'!H22 -> 27020.51 | E11: =C11+D11 -> 27020.51
A12: 7 | B12: ='[1]Items 5-8 Dismantl & Modif work'!B23 -> 33kV OHL Modification works for SHBPRY | C12: =+'Items 5-8 Dismantl & Modif work'!F23 -> 0 | D12: =+'Items 5-8 Dismantl & Modif work'!H23 -> 915054.9 | E12: =C12+D12 -> 915054.9
A13: 8 | B13: ='[1]Items 5-8 Dismantl & Modif work'!B24 -> Shifting of existing 11kV TRM (GIS name: OKH12) to a location near existing TRM (DHS08) to connect Radial Transformer (SHB02) into a ring feeder | C13: =+'Items 5-8 Dismantl & Modif work'!F24 -> 0 | D13: =+'Items 5-8 Dismantl & Modif work'!H24 -> 5000 | E13: =C13+D13 -> 5000
A14: 9 | B14: ='[1]Items 9- Spare Parts (Optional)'!B156 -> Spare Parts & Tools (Optional) | C14: =+'Items 9- Spare Parts (Optional)'!F158 -> 924738.15 | D14: N/A | E14: =C14 -> 924738.15
B15: Total Contract Price (U.A.E. Dirhams) | C15: =SUM(C6:C14) -> 29265984 | D15: =SUM(D6:D13) -> 24376521 | E15: =SUM(E6:E14) -> 53642505
A16: UAE Dirhams _____________________________________________________________

Sheet Items 1,2,3-Construction Works
A1: ABU DHABI DISTRIBUTION COMPANY
A2: TENDER NO. : D-111808
A3: CONSTRUCTION WORKS FOR REPLACEMENT OF SHBPRY, SMHPRY AND DRPRY SUBSTATION IN EASTERN REGION
A4: LOT 1: SHOBAISI PRY (SHBPRY)
A5: Item | B5: Description | C5: Unit | D5: Estimated Qty. (a) | E5: CIF / Local (AED) - A | G5: Erection (AED) - B | I5: Total Price (AED)
E6: Unit Rate (b) | F6: Total (a*b) | G6: Unit Rate (c) | H6: Total (a*c)
I7: A + B
B8: The Technical Specifications, the description of the Scope of the Work/Scope of Supply and the subsequently prepared Price Tabulation Sheets / BOQ, are intended to give the frame of the equipment needed for the items in Scope. It is to be understood that the work(s) / services /equipment include everything requisite and/or necessary to finish the entire work properly to the satisfaction of ADDC/Employer and the equipment has to be complete in every respect, notwithstanding the fact that every item may not be specifically mentioned.
B9: CONSTRUCTION OF NEW 33/11 kV PRIMARY SUBSTATION (SHBPRY) AND ASSOCIATED EXTERNAL 33kV, 11kV & PILOT CABLE DIVERSION WORKS
A10: 1 | B10: Electrical Works for new 33/11 kV Primary Substation
A11: 1.1 | B11: 33 kV GIS Switchgear
B12: Supply, Installation, testing and commissioning of the SF6 insulated (GIS) type with single busbar of 1600 A nominal current rating at 40deg.C ambient temperature and rated short-circuit current of 31.5kA for 1sec. including all the associated protection relays including relays panels, tools and accessories in line with enclosed SOW, tender specifications and drawings. As the substation will have three 33/11kV power transformers the 33kV busbar will be divided into three sections. Supply of cable terminations for all the feeder panels (surplus/unused termination kits shall be handed-over to ADDC as per procedure) shall be included. Dummy plugs shall be provided for all the feeders. 33kV switchgear must be equipped of following configuration as per SOW and tender drawing.
A13: 1.1.1 | B13: 630A incomer panels and associated relays. | C13: Nos. | D13: 3 | E13: 386916.35 | F13: =D13*E13 -> 1160749.1 | G13: 30947.059 | H13: =G13*D13 -> 92841.176 | I13: =F13+H13 -> 1253590.2
A14: 1.1.2 | B14: No BOQ Item
A15: 1.1.3 | B15: 630A outgoing/transformer feeder panels and associated relays. | C15: Nos. | D15: 3 | E15: 386916.35 | F15: =D15*E15 -> 1160749.1 | G15: 30947.059 | H15: =G15*D15 -> 92841.176 | I15: =F15+H15 -> 1253590.2
A16: 1.1.4 | B16: 1250A panels for Bus Section/Bus Riser and Measuring Cubicles | C16: Sets | D16: 2 | E16: 386916.35 | F16: =D16*E16 -> 773832.7 | G16: 30947.059 | H16: =G16*D16 -> 61894.117 | I16: =F16+H16 -> 835726.82
A17: 1.1.5 | B17: Portable gas handling equipment along with 20kg gas cylinder suitable for offered switchgear | C17: Nos. | D17: 1 | E17: 173873.25 | F17: =D17*E17 -> 173873.25 | G17: 0 | H17: =+G17*D17 -> 0 | I17: =F17+H17 -> 173873.25
A18: 1.2 | B18: 33 kV Protection Panels
B19: Supply and Installation of Control and Protection Panels for 33 kV switchgear in line with Scope of Work, tender drawings & ADDC Specifications and requirements, comprising of:
A20: 1.2.1 | B20: Incomer Cable Feeder Protection Panels | C20: Nos. | D20: 3 | E20: 233750 | F20: =D20*E20 -> 701250 | G20: 29504.44 | H20: =G20*D20 -> 88513.32 | I20: =F20+H20 -> 789763.32
A21: 1.2.2 | B21: No BOQ Item
A22: 1.2.3 | B22: Transformer Feeder Protection Panels | C22: Nos. | D22: 3 | E22: 181200 | F22: =D22*E22 -> 543600 | G22: 14546.81 | H22: =G22*D22 -> 43640.43 | I22: =F22+H22 -> 587240.43
A23: 1.2.4 | B23: Bus Sectionalizer / Bus riser Protection Panels | C23: Sets | D23: 2 | E23: 105300 | F23: =D23*E23 -> 210600 | G23: 1004.52 | H23: =G23*D23 -> 2009.04 | I23: =F23+H23 -> 212609.04
A24: 1.2.4 | B24: Portable PC (latest model) with software for parameter setting, monitoring, diagnostic, etc. for all numeric protection relays in line with Scope of Work & TAQA/ADDC Specifications and requirements | C24: Nos. | D24: 1 | E24: 62761.36 | F24: =D24*E24 -> 62761.36 | G24: 0 | H24: =G24*D24 -> 0 | I24: =F24+H24 -> 62761.36
A25: 1.3 | B25: 33 kV Busbar Protection
B26: Supply, Installation,Testing & Commisioning of 33 kV high impedance Busbar Protection in line with SOW. | C26: Lot | D26: 1 | E26: 304057.5 | F26: =D26*E26 -> 304057.5 | G26: 31519.65 | H26: =G26*D26 -> 31519.65 | I26: =F26+H26 -> 335577.15
A27: 1.4 | B27: 11kV AIS Switchgear
B28: Supply, Installation, testing and commissioning of the 11kV Switchgear shall be of Air-Insulated type and consist of a single busbar system with three sections and ring configuration. Each busbar shall have a current rating of 1600A, short circuit current 31.5 kA for 1 sec. including all the associated protection relays, tools and accessories in line with enclosed SOW, tender specifications and drawings. Dummy plugs shall be provided for all the feeders. Including Two (2) Bus Ducts for Busbar Interconnection. 11kV switchgear must be equipped of following configuration as per SOW and tender drawing.
A29: 1.4.1 | B29: 1600A incomer panels from 20MVA 33/11kV power transformers and associated relays | C29: Nos. | D29: 3 | E29: 177715.06 | F29: =D29*E29 -> 533145.19 | G29: 7670.513 | H29: =G29*D29 -> 23011.539 | I29: =F29+H29 -> 556156.73
A30: 1.4.2 | B30: 630A outgoing feeder panels and associated relays | C30: Nos. | D30: 24 | E30: 177715.06 | F30: =D30*E30 -> 4265161.5 | G30: 7670.513 | H30: =G30*D30 -> 184092.31 | I30: =F30+H30 -> 4449253.8
A31: 1.4.3 | B31: 630A outgoing feeder panels for auxiliary transformer and associated relays | C31: Nos. | D31: 2 | E31: 177715.06 | F31: =D31*E31 -> 355430.13 | G31: 7670.513 | H31: =G31*D31 -> 15341.026 | I31: =F31+H31 -> 370771.15
A32: 1.4.4 | B32: 630A outgoing feeder panels for capacitor banks and associated relays | C32: Nos. | D32: 3 | E32: 177715.06 | F32: =D32*E32 -> 533145.19 | G32: 7670.513 | H32: =G32*D32 -> 23011.539 | I32: =F32+H32 -> 556156.73
A33: 1.4.5 | B33: 1600A bus sectionalizer/bus riser panels and metering cubicles | C33: Sets | D33: 3 | E33: 177715.06 | F33: =D33*E33 -> 533145.19 | G33: 7670.513 | H33: =G33*D33 -> 23011.539 | I33: =F33+H33 -> 556156.73
A34: 1.4.7 | B34: Over-Head Bus Ducts for Busbar Interconnection | C34: Sets | D34: 2 | E34: 175809.63 | F34: =D34*E34 -> 351619.27 | G34: 1123.1215 | H34: =G34*D34 -> 2246.2431 | I34: =F34+H34 -> 353865.51
A35: 1.5 | B35: 20 MVA Power Transformer
B36: Supply, Transportation, Installation, Testing & Commissioning of 33/11.5kV Power Transformers having 20MVA rated output with Copper winding complete with AVR panel, TIP panel, cable terminations, tools and accessories in line with enclosed SOW, tender specifications and drawings. | C36: Nos | D36: 3 | E36: 1822500 | F36: =D36*E36 -> 5467500 | G36: 53887.562 | H36: =G36*D36 -> 161662.69 | I36: =F36+H36 -> 5629162.7
A37: 1.5.1 | B37: Supply, Installation, Testing & Commissioning of Automatic Voltage Regulator (AVR) Panel for Operation of the Motorized Tap Changer in line with SOW & latest TAQA/ADDC specification & requirements. | C37: Nos | D37: 3 | E37: 159246 | F37: =D37*E37 -> 477738 | G37: 14404.29 | H37: =G37*D37 -> 43212.87 | I37: =F37+H37 -> 520950.87
A38: 1.5.2 | B38: Supply, Installation, Testing & Commissioning of Transformer Interlocking Panel in line with SOW & latest TAQA/ADDC specification & requirements. | C38: Nos | D38: 1 | E38: 86725 | F38: =D38*E38 -> 86725 | G38: 4408.39 | H38: =G38*D38 -> 4408.39 | I38: =F38+H38 -> 91133.39
A39: 1.6 | B39: Auxiliary Transformer - 630kVA
B40: Supply, Transportation, Installation, Testing & Commissioning of 630kVA 11/0.415kV Auxiliary Transformer with Aluminium winding complete with cable terminations, tools and accessories in line with enclosed SOW, tender specifications and drawings. | C40: Nos | D40: 2 | E40: 81987.5 | F40: =D40*E40 -> 163975 | G40: 4281.58 | H40: =D40*G40 -> 8563.16 | I40: =F40+H40 -> 172538.16
...

Sheet Items 4-Load Diversion Works
A1: ABU DHABI DISTRIBUTION COMPANY
A2: ='[1]Items 1,2,3-Construction Works'!A2 -> TENDER NO. : D-111808
A3: ='[1]Items 1,2,3-Construction Works'!A3 -> CONSTRUCTION WORKS FOR REPLACEMENT OF SHBPRY, SMHPRY AND DRPRY SUBSTATION IN EASTERN REGION
A4: ='[1]Items 1,2,3-Construction Works'!A4 -> LOT 1: SHOBAISI PRY (SHBPRY)
A5: Item | B5: Description | C5: Unit | D5: Estimated Qty. (a) | E5: CIF / Local (AED) - A | G5: Erection (AED) - B | I5: Total Price (AED)
E6: Unit Rate (b) | F6: Total (a*b) | G6: Unit Rate (c) | H6: Total (a*c)
I7: A + B
B8: The Technical Specifications, the description of the Scope of the Work/Scope of Supply and the subsequently prepared Price Tabulation Sheets / BOQ, are intended to give the frame of the equipment needed for the items in Scope. It is to be understood that the work(s) / services /equipment include everything requisite and/or necessary to finish the entire work properly to the satisfaction of ADDC/Employer and the equipment has to be complete in every respect, notwithstanding the fact that every item may not be specifically mentioned.
A9: 4 | B9: Interconnecting Cables between Grid Station and the new Primary Substation and Load Diversion works
A10: 4.1 | B10: General Project requirements: Route Survey - NO BOQ Items
A11: 4.2 | B11: 33kV Power cables
B12: Scope shall include the following for 33 kV cables and its accessories in line with enclosed SOW, tender specifications and drawings shall be provided
A13: 4.2.1 | B13: Collection from ADDC store, Installation, Testing & Commisioning of 33kV, 3Cx400sq.mm XLPE, Al. cable from 33kV switchgear of Primary Substation to pick-up point. | C13: m | D13: 1570 | F13: =D13*E13 -> 0 | G13: 12.74 | H13: =D13*G13 -> 20001.8 | I13: =F13+H13 -> 20001.8
A14: 4.2.2 | B14: Installation, Testing & Commisioning of 33kV plug-in type cable-end termination (33kV SWGR in new Primary substation) for 3Cx400sq.mm XLPE, Al. Cable, including all accessories in line with SOW. | C14: Sets | D14: 3 | E14: included in BOQ item 1.1 | G14: 2081.25 | H14: =D14*G14 -> 6243.75 | I14: =F14+H14 -> 6243.75
A15: 4.2.3 | B15: Collection from ADDC store, Installation, Testing & Commisioning of 33 kV cable straight through joint (aluminium and aluminium cable) for 3Cx400 Sq.mm, Al XLPE, armoured cable and as per Technical Specification in line with SOW. | C15: Sets | D15: 2 | F15: =D15*E15 -> 0 | G15: 922.19 | H15: =D15*G15 -> 1844.38 | I15: =F15+H15 -> 1844.38
A16: 4.2.4 | B16: Collection from ADDC store, Installation, Testing & Commisioning of 33 kV cable straight through transition joint (aluminium and copper cable) for 3Cx400 Sq.mm, Al XLPE, armoured cable with existing Cu. XLPE, armoured cable and as per Technical Specification in line with SOW. | C16: Sets | D16: 1 | F16: =D16*E16 -> 0 | G16: 1159.06 | H16: =D16*G16 -> 1159.06 | I16: =F16+H16 -> 1159.06
A17: 4.2.5 | B17: Supply, Installation, Testing & Commissioning of 33kV Conventional-type cable-end termination (33kV Terminal Tower) for 3Cx400sq.mm XLPE, Al. Cable, including all accessories in line with SOW. | C17: Sets | D17: 2 | F17: =D17*E17 -> 0 | G17: 1697.78 | H17: =D17*G17 -> 3395.56 | I17: =F17+H17 -> 3395.56
A18: 4.3 | B18: 11kV Power cables
B19: Scope shall include the following for 11 kV cables and its accessories in line with enclosed SOW, tender specifications and drawings shall be provided
A20: 4.3.1 | B20: Collection from ADDC store, Installation, Testing & Commisioning of 11kV, 3Cx400sq.mm XLPE, Al. cable for interconnections between 11kV switchgear of each Primary Substation to pick-up point | C20: m | D20: 10485 | F20: =D20*E20 -> 0 | G20: 12.74 | H20: =D20*G20 -> 133578.9 | I20: =F20+H20 -> 133578.9
A21: 4.3.2 | B21: Installation, Testing & Commisioning of 11kV conventional-type cable-end termination (11kV SWGR in new Primary Substation) for 3Cx400sq.mm XLPE, Al. Cable, including all accessories in line with SOW. | C21: Sets | D21: 13 | E21: included in BOQ item 1.4 | G21: 801.42 | H21: =D21*G21 -> 10418.46 | I21: =F21+H21 -> 10418.46
A22: 4.3.3 | B22: Collection from ADDC store, Installation, Testing & Commisioning of 11kV conventional-type bi-metallic cable-end termination (downstream 11kV RMU/SWGR) for 3Cx400sq.mm XLPE, Al. Cable, including all accessories in line with SOW. | C22: Sets | D22: 5 | F22: =D22*E22 -> 0 | G22: 801.42 | H22: =D22*G22 -> 4007.1 | I22: =F22+H22 -> 4007.1
A23: 4.3.4 | B23: Collection from ADDC store, Installation, Testing & Commisioning of 11 kV cable straight through joint (aluminium and aluminium cable) for 3Cx400 Sq.mm, Al XLPE, armoured cable and as per Technical Specification in line with SOW. | C23: Sets | D23: 20 | F23: =D23*E23 -> 0 | G23: 801.42 | H23: =D23*G23 -> 16028.4 | I23: =F23+H23 -> 16028.4
A24: 4.3.5 | B24: Collection from ADDC store, Installation, Testing & Commisioning of 11 kV cable straight through transition joint (aluminium and copper cable) for 3Cx400 Sq.mm, Al XLPE, armoured cable with existing 3Cx400 Sq.mm, Cu XLPE, armoured cable and as per Technical Specification in line with SOW. | C24: Sets | D24: 12 | F24: =D24*E24 -> 0 | G24: 919.85 | H24: =D24*G24 -> 11038.2 | I24: =F24+H24 -> 11038.2
A25: 4.4 | B25: Pilot wire
B26: Scope shall include the following for Pilot wire and its accessories in line with enclosed SOW, tender specifications and drawings shall be provided
A27: 4.4.1 | B27: Collection from ADDC store (free issue), Installation, Testing & Commissioning of Armoured Pilot wire for communcation and protection purpose in line with SOW. | C27: m | D27: 2150 | F27: =D27*E27 -> 0 | G27: 4.24 | H27: =D27*G27 -> 9116 | I27: =F27+H27 -> 9116
A28: 4.4.2 | B28: Supply, Installation, Testing & Commissioning of Pilot wire end joint including all accessories for conneting new pilot wire with existing pilot wire in line with SOW. | C28: Sets | D28: 2 | F28: =D28*E28 -> 0 | G28: 5685.97 | H28: =D28*G28 -> 11371.94 | I28: =F28+H28 -> 11371.94
A29: 4.4.3 | B29: Supply, Installation of Pilot wire termination box including all accessories in line with SOW & ADDC requirements | C29: Nos. | D29: 2 | F29: =D29*E29 -> 0 | G29: 17249.58 | H29: =D29*G29 -> 34499.16 | I29: =F29+H29 -> 34499.16
A30: 4.4.4 | B30: Supply, Installation of Pilot wire to FO cable convertor box including all accessories in line ADDC requirements | C30: Nos. | D30: 4 | F30: =D30*E30 -> 0 | G30: 19166.2 | H30: =D30*G30 -> 76664.8 | I30: =F30+H30 -> 76664.8
A31: 4.5 | B31: Fibre Optic (FO) Cables and Accessories
A32: 4.5.1 | B32: Supply, Installation, Testing & Commisioning of Floor mounted panel suitable for termination of Two (2) of fibre optic cable and FO patch cards including two (2) termination head racks complete at new 33/11kV Primary Substation including all accessories in line ADDC requirements | C32: Lot | D32: 1 | F32: =D32*E32 -> 0 | G32: 111802.86 | H32: =D32*G32 -> 111802.86 | I32: =F32+H32 -> 111802.86
A33: 4.5.2 | B33: Supply, Installation, Testing & Commisioning of New Wall mounted fiber optic termination box complete with suitable for termination of 32-core FOC at remote end substation including all accessories in line ADDC requirements | C33: Nos. | D33: 2 | F33: =D33*E33 -> 0 | G33: 9583.1 | H33: =D33*G33 -> 19166.2 | I33: =F33+H33 -> 19166.2
A34: 4.6 | B34: Civil Works for External cable laying works
B35: The scope of work of this item covers the engineering, design, execution, commissioning and warranty services for all civil works related to the installation of the 33kV cables, 11kV and pilot cables specified for the new 33/11kV Primary substation in line with Scope of Work- NO BOQ Items
A36: 4.7 | B36: Excavate trench of appropriate width and depth as per ADDC Specification including dewatering, in ground of any nature, in any formation for multiple HV & pilot cable laying in the same trench, backfill the same including sand bedding and reinstate. | C36: m3 | D36: =(D13+D20+D27)*0.5*1 -> 7102.5 | F36: =D36*E36 -> 0 | G36: 64.12 | H36: =D36*G36 -> 455412.3 | I36: =F36+H36 -> 455412.3
A37: 4.7.1 | B37: Excavate trench of appropriate width and depth in Green area as per ADDC Specification including dewatering, in ground of any nature, in any formation for multiple HV & pilot cable laying in the same trench, backfill the same including sand bedding and reinstate. | C37: m3 | D37: 10 | F37: =D37*E37 -> 0 | G37: 64.12 | H37: =D37*G37 -> 641.2 | I37: =F37+H37 -> 641.2
A38: 4.8 | B38: Earthing materials for Power & pilot cables, cable tray & cable supports | C38: Lot | D38: 1 | F38: =D38*E38 -> 0 | G38: 46737.25 | H38: =D38*G38 -> 46737.25 | I38: =F38+H38 -> 46737.25
A39: 4.9 | B39: Supply and laying of LDPE-Recycled (Low Density Poly Ethylene with dimension of 1000 x 250 x 6 mm cable covering protective tiles for 33kV, 11kV power & pilot cable as per TAQA/ADDC Technical Specification in line with SOW. | C39: Nos | D39: =(D13*2)+(D20*1)+(D27*1) -> 15775 | F39: =D39*E39 -> 0 | G39: 9.21 | H39: =D39*G39 -> 145287.75 | I39: =F39+H39 -> 145287.75
A40: 4.1 | B40: Warning tape, 300 mm width and 150 microns thick, along the cable in trench for 33kV, 11kV cables & pilot cable and as per Technical Specification in line with SOW. | C40: m | D40: =D13+D20+D27 -> 14205 | F40: =D40*E40 -> 0 | G40: 0.9 | H40: =D40*G40 -> 12784.5 | I40: =F40+H40 -> 12784.5
...

Sheet Items 5-8 Dismantl & Modif work
A1: ABU DHABI DISTRIBUTION COMPANY
A2: ='[1]Items 1,2,3-Construction Works'!A2 -> TENDER NO. : D-111808
A3: ='[1]Items 1,2,3-Construction Works'!A3 -> CONSTRUCTION WORKS FOR REPLACEMENT OF SHBPRY, SMHPRY AND DRPRY SUBSTATION IN EASTERN REGION
A4: ='[1]Items 1,2,3-Construction Works'!A4 -> LOT 1: SHOBAISI PRY (SHBPRY)
A5: Item | B5: Description | C5: Unit | D5: Estimated Qty. (a) | E5: CIF / Local (AED) - A | G5: Erection (AED) - B | I5: Total Price (AED)
E6: Unit Rate (b) | F6: Total (a*b) | G6: Unit Rate (c) | H6: Total (a*c)
I7: A + B
B8: The Technical Specifications, the description of the Scope of the Work/Scope of Supply and the subsequently prepared Price Tabulation Sheets / BOQ, are intended to give the frame of the equipment needed for the items in Scope. It is to be understood that the work(s) / services /equipment include everything requisite and/or necessary to finish the entire work properly to the satisfaction of ADDC/Employer and the equipment has to be complete in every respect, notwithstanding the fact that every item may not be specifically mentioned.
A9: 5 | B9: Dismantling, Decommissioning & Demolition Works of existing old 33/11kV primary substation (SHBPRY)
A10: 5.1 | B10: Decommissioning, Dismantling, Demolish, Packing and handing over safely of all the existing substation equipment and materials to ADDC stores as per standard ADDC procedure in line with Scope of Work. | C10: Lot | D10: 1 | F10: =D10*E10 -> 0 | G10: 193226.5 | H10: =D10*G10 -> 193226.5 | I10: =F10+H10 -> 193226.5
A11: 6 | B11: Dismantling & Decommissioning Works of old 2 nos. Package Units (SHBPRY2 & SHBPRY3)
A12: 6.1 | B12: Scope of work shall include the existing SHBPRY2 & SHBPRY3 old package units, Decommissioning, Dismantling, Packing and handing over safely of the existing package unit and its equipment and materials to ADDC stores as per standard ADDC procedure in line with Scope of Work. | C12: Lot | D12: 1 | F12: =D12*E12 -> 0 | G12: 27020.51 | H12: =D12*G12 -> 27020.51 | I12: =F12+H12 -> 27020.51
A13: 7 | B13: 33kV OHL Modification works for SHBPRY
B14: The scope of work of this item covers the engineering, design, execution, commissioning and warranty services for all electrical and civil works related to necessary OHL modification works as part of 33kV OHL modification and diversion works for SHBPRY.
A15: 7.1 | B15: Supply, Installation, Testing and Commissioning of 33kV OHL terminal tower double circuit including all accessories as detailed in SOW for proposed termination of proposed 33kV, 3Cx400sq.mm Al. XLPE cables with existing conductor as per relevant Technical Specification. Refer to network diagram for installation and modification in line with SOW. | C15: Lot | D15: 1 | F15: =D15*E15 -> 0 | G15: 760354.9 | H15: =D15*G15 -> 760354.9 | I15: =F15+H15 -> 760354.9
A16: 7.2 | B16: Dismantling & Decommissioning of existing 33kV OHL line including Tower / Conductor and Handover To ADDC Store (after successful diversion to new proposed SHBPRY as per tender documents in line with SOW) | C16: M | D16: 1000 | F16: =D16*E16 -> 0 | G16: 154.7 | H16: =D16*G16 -> 154700 | I16: =F16+H16 -> 154700
A17: Item-7 Sub Total - 33kV OHL Modification works for SHBPRY | F17: =SUM(F15:F16) -> 0 | H17: =SUM(H15:H16) -> 915054.9 | I17: =SUM(I15:I16) -> 915054.9
A18: 8 | B18: Shifting of existing 11kV TRM (GIS name: OKH12) to a location near existing TRM (DHS08) to connect Radial Transformer (SHB02) into a ring feeder
A19: 8.1 | B19: The scope of work comprises of the shifting, Installation, testing and commissioning of existing 11kV TRM including all necessary cable terminations as per standard ADDC procedure in line with Scope of Work. | C19: Lot | D19: 1 | F19: =D19*E19 -> 0 | G19: 5000 | H19: =D19*G19 -> 5000 | I19: =F19+H19 -> 5000
A21: Item - 5 | B21: =B9 -> Dismantling, Decommissioning & Demolition Works of existing old 33/11kV primary substation (SHBPRY) | F21: =F10 -> 0 | H21: =H10 -> 193226.5 | I21: =I10 -> 193226.5
A22: Item - 6 | B22: =B11 -> Dismantling & Decommissioning Works of old 2 nos. Package Units (SHBPRY2 & SHBPRY3) | F22: =F12 -> 0 | H22: =H12 -> 27020.51 | I22: =I12 -> 27020.51
A23: Item - 7 | B23: =B13 -> 33kV OHL Modification works for SHBPRY | F23: =F17 -> 0 | H23: =H17 -> 915054.9 | I23: =I17 -> 915054.9
A24: Item - 8 | B24: =B18 -> Shifting of existing 11kV TRM (GIS name: OKH12) to a location near existing TRM (DHS08) to connect Radial Transformer (SHB02) into a ring feeder | F24: =F19 -> 0 | H24: =H19 -> 5000 | I24: =I19 -> 5000
A26: GRAND TOTAL of Items-5, 6, 7, 8 Works (Prices) | F26: =SUM(F21:F24) -> 0 | H26: =SUM(H21:H24) -> 1140301.9 | I26: =SUM(I21:I24) -> 1140301.9

Sheet Items 9- Spare Parts (Optional)
A1: ABU DHABI DISTRIBUTION COMPANY
A2: ='[1]Items 1,2,3-Construction Works'!A2 -> TENDER NO. : D-111808
A3: ='[1]Items 1,2,3-Construction Works'!A3 -> CONSTRUCTION WORKS FOR REPLACEMENT OF SHBPRY, SMHPRY AND DRPRY SUBSTATION IN EASTERN REGION
A4: ='[1]Items 1,2,3-Construction Works'!A4 -> LOT 1: SHOBAISI PRY (SHBPRY)
A5: Item | B5: Description | C5: Unit | D5: Estimated Qty. (a) | E5: CIF / Local (AED) - A
E6: Unit Rate (b) | F6: Total (a*b)
B8: The Technical Specifications, the description of the Scope of the Work/Scope of Supply and the subsequently prepared Price Tabulation Sheets / BOQ, are intended to give the frame of the equipment needed for the items in Scope. It is to be understood that the work(s) / services /equipment include everything requisite and/or necessary to finish the entire work properly to the satisfaction of ADDC/Employer and the equipment has to be complete in every respect, notwithstanding the fact that every item may not be specifically mentioned.
A9: 9 | B9: Spare Parts & Tools (Optional)
A10: 9.1 | B10: 33kV Switchgear (GIS)
A11: 9.1.1 | B11: Complete circuit breaker unit(s) of each rating/type supplied , including operation mechansium | C11: Set | D11: 1 | E11: 198617.48 | F11: =D11*E11 -> 198617.48
A12: 9.1.2 | B12: Auxiliary switch | C12: No. | D12: 1 | E12: 359.95333 | F12: =D12*E12 -> 359.95333
A13: 9.1.3 | B13: Spring tensioning motor | C13: No. | D13: 1 | E13: 642.77667 | F13: =D13*E13 -> 642.77667
A14: 9.1.4 | B14: Closing/trip solenoid coils | C14: Nos. | D14: 2 | E14: 128.55667 | F14: =D14*E14 -> 257.11333
A15: 9.1.5 | B15: Operating mechanism (Not Applicable) | C15: No. | D15: 1 | E15: 0 | F15: =D15*E15 -> 0
A16: 9.1.6 | B16: Complete busbar disconnector/earthing switch unit for each current rating with operating mechanism (Not Applicable) | C16: Set | D16: 1 | E16: 0 | F16: =D16*E16 -> 0
A17: 9.1.7 | B17: Complete VT disconnector switch with main operating mechanism | C17: Set | D17: 1 | E17: 964.16333 | F17: =D17*E17 -> 964.16333
A18: 9.1.8 | B18: Auxiliary switch for disconnector/earth switch | C18: No. | D18: 1 | E18: 411.37667 | F18: =D18*E18 -> 411.37667
A19: 9.1.9 | B19: Motor for disconnector/earth switch | C19: No. | D19: 1 | E19: 514.22 | F19: =D19*E19 -> 514.22
A20: 9.1.10 | B20: Insulator-rod for disconnector/earthing switch of each type (Not Applicable) | C20: Set | D20: 1 | E20: 0 | F20: =D20*E20 -> 0
A21: 9.1.11 | B21: Complete Voltage transformer (3-Phase) | C21: Set | D21: 1 | E21: 30467.537 | F21: =D21*E21 -> 30467.537
A22: 9.1.12 | B22: Complete CT (3-Phase one of each type) | C22: L.S | D22: 1 | E22: 11569.95 | F22: =D22*E22 -> 11569.95
... A27: 9.1.17 | B27: Maintenance tools and accessories as required | C27: No. | D27: 1 | E27: 2342.2733 | F27: =D27*E27 -> 2342.2733
A28: Item-9.1 Sub Total | F28: =SUM(F11:F27) -> 269104.44
A29: 9.2 | B29: 11kV Switchgear (AIS)
A30: 9.2.1 | B30: Maintenance tools and accessories as required | C30: Set | D30: 1 | E30: 13883.94 | F30: =D30*E30 -> 13883.94
A31: 9.2.2 | B31: Circuit breaker truck(s) of each rating/type supplied, including operating mechanism | C31: Set | D31: 1 | E31: 48850.9 | F31: =D31*E31 -> 48850.9
A32: 9.2.3 | B32: Feeder isolator/earting switch(s) of each rating/type supplied | C32: Set | D32: 1 | E32: 19283.25 | F32: =D32*E32 -> 19283.25
A33: 9.2.4 | B33: Current transformer (3-Phase one of each type) | C33: Set | D33: 1 | E33: 20825.91 | F33: =D33*E33 -> 20825.91
A34: 9.2.5 | B34: Voltage transformer of each type (3-Phase) | C34: Set | D34: 1 | E34: 17354.927 | F34: =D34*E34 -> 17354.927
A35: 9.2.6 | B35: Motors of each type supplied | C35: Set | D35: 1 | E35: 642.77667 | F35: =D35*E35 -> 642.77667
A36: 9.2.7 | B36: Trip coil, fuses, aux. relays and contactors, etc. | C36: Set | D36: 1 | E36: 5913.53 | F36: =D36*E36 -> 5913.53
A37: 9.2.8 | B37: Cable Live Indicator | C37: Set | D37: 1 | E37: 1028.44 | F37: =D37*E37 -> 1028.44
A38: Item-9.2 Sub Total | F38: =SUM(F30:F37) -> 127783.67
A39: 9.3 | B39: Power Transformers 20 MVA Note: for each of the above (to be reproduced as applicable)
A40: 9.3.1 | B40: Complete bushing | C40: Set | D40: 1 | E40: 4316.6667 | F40: =D40*E40 -> 4316.6667
A41: 9.3.2 | B41: Post insulator | C41: Set | D41: 1 | E41: 1963.3333 | F41: =D41*E41 -> 1963.3333
A42: 9.3.3 | B42: Temperature monitor | C42: Set | D42: 1 | E42: 4906.6667 | F42: =D42*E42 -> 4906.6667
A43: 9.3.4 | B43: Thermometer | C43: Set | D43: 1 | E43: 4906.6667 | F43: =D43*E43 -> 4906.6667
A44: 9.3.5 | B44: Oil level gauge | C44: Set | D44: 1 | E44: 1963.3333 | F44: =D44*E44 -> 1963.3333
A45: 9.3.6 | B45: Step position transmitter | C45: Set | D45: 1 | E45: 3926.6667 | F45: =D45*E45 -> 3926.6667
...
