Workbook

Sheet Project Summary 
B5: PROJECT SUMMARY SHEET | C5: PROJECT SUMMARY SHEET
A6: Bill No. | B6: Description | C6: Total Costs Excluding VAT (AED)
A7: 1 | B7: GENERAL ITEMS | C7: ='GENERAL ITEMS'!F29 -> 6055000
A8: 2 | B8: AL DHAHER | C8: ='ALDhaher-Summary '!C13 -> 12197351
A9: 3 | B9: NAHEL | C9: ='Nahel-Summary '!C13 -> 14475731
A10: 4 | B10: AL SAAD | C10: ='AL SAAD-Summary '!C13 -> 15821230
A11: 5 | B11: SWEIHAN | C11: ='SWEIHAN-Summary '!C13 -> 12532257
A12: 6 | B12: DAYWORKS | C12: ='DAYWORKS-Bill 06'!F92 -> 166171.5
B14: Total Costs Excluding VAT ( AED) | C14: =SUM(C7:C12) -> 61247740
B15: Total Value Added Tax (VAT/5%) (AED) | C15: =C14*0.05 -> 3062387
B16: Total Costs Including VAT (AED) | C16: =SUM(C14:C15) -> 64310127
B19: Total Costs in Words Excluding VAT (AED): | C19: Dirhams Sixty-one million, two hundred forty-seven thousand, seven hundred forty.
B20: VAT Amount in Words (AED): | C20: Dirhams Three million, sixty-two thousand, three hundred eighty-seven
B21: Total Costs in Words Including VAT (AED): | C21: Dirhams Sixty-four million, three hundred ten thousand, one hundred twenty-seven and one Fils

Sheet GENERAL ITEMS
B5: Bill No.1, GENERAL ITEMS
A6: Sl.No | B6: Description | C6: UNIT | D6: Quantity (Q) | E6: Unit Rate AED (A) | F6: Total Line Costs Ecxluding VAT B= AED (Q X A)
A7: 1.01 | B7: Procedures
B8: Allow for all costs involved in the preparation and submission of all procedures, co-ordination, method statements etc., required for the implementation of the works such as construction and shutdown requirements, testing and commissioning etc. all according to specifications | C8: Lump sum | D8: 1 | E8: 50000 | F8: =$D8*E8 -> 50000
A9: 1.02 | B9: Planning and Progress Reporting
B10: Allow for all costs involved in the preparation and submission of daily, weekly and monthly planning and progress reporting including reports, photographs etc. all according to specifications. | C10: Lump sum | D10: 1 | E10: 15000 | F10: =$D10*E10 -> 15000
A11: 1.03 | B11: Design, Shop Drawings & Documents
A12: 1.03.1 | B12: Allow for all costs involved in the preparation and submission of all required drawings (compatible with TAQA 's Version of Auto CAD) including all details, shop drawings, vendor drawings, calculations, sketches, graphs and other documentation associated with the work, all according to specifications and according to TAQA GIS specifications. | C12: Lump sum | D12: 1 | E12: 350000 | F12: =$D12*E12 -> 350000
A13: 1.04 | B13: AS-BUILT DOCUMENTATION
B14: Allow for all costs involved in the preparation and submission of As-Built Drawings (compatible with TAQA's Version of Auto CAD) showing accurately to scale full details of installation, sizes and dimensions of pipes, connections, etc., as constructed, all according to specifications and according to TAQA GIS specifications and to be submitted as follows :
A15: 1.04.1 | B15: Three (3) sets of all As-Built drawings compatible with TAQA GIS specifications and projection for new drawings and scanned for existing modified drawings submitted in computer DVD or compacted discs (CD) | C15: Lump sum | D15: 1 | E15: 25000 | F15: =$D15*E15 -> 25000
A16: 1.04.2 | B16: Three (3) sets including soft copies of all As Built drawings to be submitted to the TPD as per the TPD requirements and as per the CDMS license agreement including obtaining the final approval of the TPD for the As Built Drawings | C16: Lump sum | D16: 1 | E16: 25000 | F16: =$D16*E16 -> 25000
A17: 1.04.3 | B17: Three (3) sets of As-Built Record Manuals containing all documents of equipment, materials etc. used for the project with records of their test certificates, calibration, and setting values all properly indexed and bounded in size files with hard covers. | C17: Lump sum | D17: 1 | E17: 25000 | F17: =$D17*E17 -> 25000
A18: 1.05 | B18: OPERATION AND MAINTENANCE MANUALS
A19: 1.05.1 | B19: Allow for all costs involved in the preparation and submission of one (1) set of operation and maintenance manuals (hard +soft copy) containing clear and precise instructions of operation and maintenance procedures with reference to the appropriate drawings and inclusive of the required related As-Built drawings. | C19: Lump sum | D19: 1 | E19: 25000 | F19: =$D19*E19 -> 25000
A20: 1.06 | B20: TEMPORARY FACILITIES FOR TQD Engineer (SITE OFFICE)
A21: 1.06.1 | B21: Allow for all costs involved in provision of the required temporary facilities (site office) and services for the sole use of TAQA / Engineers all in accordance with the Specification. | C21: Lump sum | D21: 1 | E21: 3200000 | F21: =$D21*E21 -> 3200000
A22: 1.06.2 | B22: Maintenance and running cost for above site office for TAQA Engineer during construction period complete as specified. | C22: Lump sum | D22: 1 | E22: 180000 | F22: =$D22*E22 -> 180000
A23: 1.07 | B23: Temporary Facilities for Construction
A24: 1.07.1 | B24: Allow for all costs involved in setting up, maintenance, running costs etc. for all required temporary facilities for the construction including site preparation, workshops, fabrication yards, stores, sheds, site office, accommodation, first aid facilities, access roads etc. all according to the specification. | C24: Lump sum | D24: 1 | E24: 2000000 | F24: =$D24*E24 -> 2000000
A25: 1.08 | B25: Mobilization
A26: 1.08.1 | B26: Allow for all costs involved in mobilization of all labor, supervision personnel, construction material, equipment & plant, transport, consumables etc. which are required to set up the site including site office, fire and safety equipment all according to specifications. | C26: Lump sum | D26: 1 | E26: 120000 | F26: =$D26*E26 -> 120000
A27: 1.09 | B27: Demobilization
A28: 1.09.1 | B28: Allow for all costs for demobilization of personnel and removal from site of all constructional plant, surplus material, site offices, rubbish, temporary work and any other kind of works not being part of the permanent works and leave the whole of the site and work, clean and in a workmanlike condition to the satisfaction of the TAQA Engineer. | C28: Lump sum | D28: 1 | E28: 40000 | F28: =$D28*E28 -> 40000
B29: Total Costs for Bill No.1 excluding VAT (AED) | F29: =SUM(F8:F28) -> 6055000

Sheet ALDhaher-Summary 
B5: SUMMARY SHEET- AL DHAHER
A6: Bill No. | B6: Description | C6: Total Costs Excluding VAT (AED)
A7: 1 | B7: SUPPLY OF PIPEWORKS | C7: ='AL Dhaher Bill 01'!F47 -> 673272.09
A8: 2 | B8: CIVIL WORKS | C8: ='AL Dhaher-Bill 02'!F121 -> 3543338.8 | E8: .
A9: 3 | B9: ELECTRICAL WORKS | C9: ='AL Dhaher-Bill 03'!F82 -> 2504427.1
A10: 4 | B10: CONSTRUCTION OF PIPELINES | C10: ='AL Dhaher-Bill 04'!F48 -> 380969.59
A11: 5 | B11: INSTRUMENTATION AND CONTROL/ SCADA | C11: ='AL Dhaher-Bill 05'!F41 -> 5095343.2
B13: Total Costs Excluding VAT ( AED) | C13: =SUM(C7:C11) -> 12197351
B14: Total Value Added Tax (VAT/5%) (AED) | C14: =C13*0.05 -> 609867.54
B15: Total Costs Including VAT (AED) | C15: =SUM(C13:C14) -> 12807218
B18: Total Costs in Words Excluding VAT (AED): | C18: Dirhams Twelve million, one hundred ninety-seven thousand, three hundred fifty and seventy-six Fils
B19: VAT Amount in Words (AED): | C19: Dirhams Six hundred nine thousand, eight hundred sixty-seven and fifty-four Fils
B20: Total Costs in Words Including VAT (AED): | C20: Dirhams Twelve million, eight hundred seven thousand, two hundred eighteen and thirty Fils

Sheet AL Dhaher Bill 01
B5: Bill No.1, SUPPLY OF PIPEWORKS
A6: Sl.No | B6: Description | C6: UNIT | D6: Quantity (Q) | E6: Unit Rate AED (A) | F6: Total Line Costs Ecxluding VAT B= AED (Q X A)
B7: Storm Water Works
A8: 1.001 | B8: Supply the following ISO standard uPVC including warning tape and all other accessories as per TAQA standard specifications | C8: Lump Sum | D8: 1 | E8: 4147.3461 | F8: =$D8*E8 -> 4147.3461
B9: Sewerage Works
A10: 1.002 | B10: Supply the following ISO standard uPVC including warning tape and all other accessories as per TAQA standard specifications | C10: Lump Sum | D10: 1 | E10: 2862.4256 | F10: =$D10*E10 -> 2862.4256
B11: Gully Trap
A12: 1.003 | B12: Supply the following ISO standard Gully trap including all other accessories as per TAQA standard specifications | C12: Lump Sum | D12: 1 | E12: 225.86715 | F12: =$D12*E12 -> 225.86715
B13: Potable Water Works
B14: Ductile Iron (DI) Pipe
B15: Supply and Install DI pipe as specified complete with installation of detectable warning tapes and other accessories all in accordance with TAQA standard specification, data sheet and drawings.
A16: 1.004 | B16: DI - Standard Socket Spigot pipes | C16: Lump Sum | D16: 1 | E16: 65745.943 | F16: =$D16*E16 -> 65745.943
B17: HDPE Pipe
A18: 1.005 | B18: Supply ISO Standard HDPE pipes, fittings, all in accordance with TAQA standard specification, data sheet and drawings. | C18: Lump Sum | D18: 1 | E18: 52597.628 | F18: =$D18*E18 -> 52597.628
B19: Gate Valves
A20: 1.006 | B20: Supply of PN 16 Manual Gate Valves above ground in accordance with specification, drawings and data sheet. | C20: Lump Sum | D20: 1 | E20: 3811.1852 | F20: =$D20*E20 -> 3811.1852
B21: Air Valves
A22: 1.007 | B22: Supply of Air Valves in accordance with specification, drawings and data sheet. | C22: Lump Sum | D22: 1 | E22: 3241.9362 | F22: =$D22*E22 -> 3241.9362
B23: Bulk Connection Chamber Valves & Fittings
A24: 1.008 | B24: Supply of Manual Check Valves & Fittings in accordance with specification, drawings and data sheet. | C24: Lump Sum | D24: 1 | E24: 10605.084 | F24: =$D24*E24 -> 10605.084
A25: 1.009 | B25: Supply of Manual Butterfly Valves & Fittings in accordance with specification, drawings and data sheet. | C25: Lump Sum | D25: 1 | E25: 10297.676 | F25: =$D25*E25 -> 10297.676
A26: 1.01 | B26: Supply of Settlement Type Electromagnetic Flow Meter & Fittings on 355mm dia line in accordance with specification, drawings and data sheet. | C26: Lump Sum | D26: 1 | E26: 56222.749 | F26: =$D26*E26 -> 56222.749
A27: 1.011 | B27: Supply of Control Valve & Fittings in accordance with specification, drawings and data sheet. | C27: Lump Sum | D27: 1 | E27: 36220.094 | F27: =$D27*E27 -> 36220.094
B28: Flange Connection Chamber Fittings
A29: 1.012 | B29: Supply of Flange Connection Chamber Fittings in accordance with specification, drawings and data sheet. | C29: Lump Sum | D29: 1 | E29: 808.10245 | F29: =$D29*E29 -> 808.10245
B30: Wash Out Valves
A31: 1.013 | B31: Supply of Wash Out Valves in accordance with specification, drawings and data sheet. | C31: Lump Sum | D31: 1 | E31: 9222.9458 | F31: =$D31*E31 -> 9222.9458
B32: Bip Tap
A33: 1.014 | B33: Supply of BIP TAP including all fittings and accessories | C33: Lump Sum | D33: 1 | E33: 451.73429 | F33: =$D33*E33 -> 451.73429
B34: Flow Meter Validation Unit
A35: 1.015 | B35: Supply flow meter validation unit with validation software all as per specifications. The unit shall be supplied with power supply with rechargeable batteries and integral charger unit. | C35: Lump Sum | D35: 1 | E35: 32123.327 | F35: =$D35*E35 -> 32123.327
B36: Flow Control Valve
A37: 1.015a | B37: Supply a flow control valve for the above-ground (vertical pipeline) validation unit, complete with validation software, in full compliance with the project specifications. The unit shall include a power supply with rechargeable batteries and an integral charging unit, ensuring continuous and reliable operation. All components shall be suitable for the intended application and delivered ready for installation and commissioning. | C37: Lump Sum | D37: 1 | E37: 52063.269 | F37: =$D37*E37 -> 52063.269
B38: Electromagnetic Flow Meter
A39: 1.016 | B39: Supply of 4" flow meter. all in accordance with specification, data sheet and drawings. | C39: Lump Sum | D39: 1 | E39: 292655.72 | F39: =$D39*E39 -> 292655.72
B40: PPR Pipes
A41: 1.017 | B41: Supply , PPR 20-25mm pipes Including valves and chambers all as specified and shown on drawings. | C41: Lump Sum | D41: 1 | E41: 2234.1875 | F41: =$D41*E41 -> 2234.1875
B42: Flexible hoses
A43: 1.018 | B43: Supply of PN 16 Flexible hoses of sufficient length, with one end flanged and necessary attachments including fasteners, gaskets etc. for filling bays as specified. | C43: Lump Sum | D43: 1 | E43: 24694.808 | F43: =$D43*E43 -> 24694.808
B44: Booster Set
...

Sheet AL Dhaher-Bill 02
C1: _
B5: Bill No.2, CIVIL WORKS
A6: Sl.No | B6: Description | C6: UNIT | D6: Quantity (Q) | E6: Unit Rate AED (A) | F6: Total Line Costs Ecxluding VAT B= AED (Q X A)
B7: Trial trench and Trial pits
A8: 2.001 | B8: Trial trench and Trial pits | C8: Lump Sum | D8: 1 | E8: 6512.0008 | F8: =$D8*E8 -> 6512.0008
B9: Trenches for Pipelines
B10: Excavate and Backfill Trenches for Pipelines
B11: Excavate, dewater and backfill trenches for pipelines including shoring, surveying, etc. for a maximum cover to pipelines of 1.2 m as per specification and as shown in drawings for the following sizes of pipelines
B12: PPR Pipelines
A13: 2.002 | B13: PPR Pipelines | C13: Lump Sum | D13: 1 | E13: 16716.137 | F13: =$D13*E13 -> 16716.137
B14: DI Pipelines
A15: 2.003 | B15: DI Pipelines | C15: Lump Sum | D15: 1 | E15: 69669.435 | F15: =$D15*E15 -> 69669.435
B16: HDPE Pipelines
A17: 2.004 | B17: HDPE Pipelines | C17: Lump Sum | D17: 1 | E17: 85982.062 | F17: =$D17*E17 -> 85982.062
B18: uPVC Pipelines for Storm Water Works
A19: 2.005 | B19: uPVC Pipelines | C19: Lump Sum | D19: 1 | E19: 19225.772 | F19: =$D19*E19 -> 19225.772
B20: uPVC Pipelines for Sewerage Works
A21: 2.006 | B21: uPVC Pipelines | C21: Lump Sum | D21: 1 | E21: 16716.137 | F21: =$D21*E21 -> 16716.137
B22: E.O.I for Excavate and Backfill Trenches for Pipelines
B23: E.O.I. for excavation of every additional 500 mm excavation depth exceeding 1.2 m cover, including dewatering, shoring, backfilling and disposal of surplus material all as per specification for the following sizes of pipelines
B24: PPR Pipelines
A25: 2.007 | B25: PPR Pipelines | C25: Lump Sum | D25: 1 | E25: 4920.8528 | F25: =$D25*E25 -> 4920.8528
B26: DI Pipelines
A27: 2.008 | B27: DI Pipelines | C27: Lump Sum | D27: 1 | E27: 4920.8528 | F27: =$D27*E27 -> 4920.8528
B28: HDPE Pipelines
A29: 2.009 | B29: DI Pipelines | C29: Lump Sum | D29: 1 | E29: 4920.8528 | F29: =$D29*E29 -> 4920.8528
B30: uPVC Pipelines for Storm Water Works
A31: 2.01 | B31: uPVC Pipelines | C31: Lump Sum | D31: 1 | E31: 4920.8528 | F31: =$D31*E31 -> 4920.8528
B32: uPVC Pipelines for Sewerage Works
A33: 2.011 | B33: uPVC Pipelines | C33: Lump Sum | D33: 1 | E33: 4920.8528 | F33: =$D33*E33 -> 4920.8528
A34: 2.012 | B34: E.O.I for excavation in rock using rock breaker including disposal of excavated material as per the Municipality requirements - the rock should be classified as per specs by lab test | C34: Lump Sum | D34: 1 | E34: 4920.8528 | F34: =$D34*E34 -> 4920.8528
A35: 2.013 | B35: E.O.I. for supply, place and compact aPPRoved imported bedding / fill material/gatch including disposal of surplus material as per specifications and as ordered and authorized by TAQA Engineer | C35: Lump Sum | D35: 1 | E35: 4920.8528 | F35: =$D35*E35 -> 4920.8528
A36: 2.014 | B36: General excavation for any other purpose including dewatering, backfilling as required or instructed by TAQA Engineer. | C36: Lump Sum | D36: 1 | E36: 22741.229 | F36: =$D36*E36 -> 22741.229
B37: Construction of Manholes and Facilities at Pipelines for Storm Water Works
A38: 2.015 | B38: Manholes including excavation, dewatering, shoring, backfilling, concrete works including the Removable cover slab, benching, blinding and screeds connection joints and protection coating to all internal concrete surfaces, waterproofing , tanking , heavy duty ductile cover & frame, complete in all respect as detailed on drawing and as per specification | C38: Lump Sum | D38: 1 | E38: 77523.116 | F38: =$D38*E38 -> 77523.116
B39: Construction of Manholes and Facilities at Pipelines for Sewer Works
A40: 2.016 | B40: Manholes including excavation, dewatering, shoring, backfilling, concrete works including the Removable cover slab, benching, blinding and screeds connection joints and protection coating to all internal concrete surfaces, waterproofing , tanking , heavy duty ductile cover & frame, complete in all respect as detailed on drawing and as per specification | C40: Lump Sum | D40: 1 | E40: 91075.144 | F40: =$D40*E40 -> 91075.144
A41: 2.017 | B41: Construction Storm water channels excavation, dewatering, shoring, backfilling, concrete works including the gratings complete in all respect as detailed on drawing and as per specification | C41: Lump Sum | D41: 1 | E41: 148452.34 | F41: =$D41*E41 -> 148452.34
A42: 2.018 | B42: Construction of Concrete support (thrust blocks) for fittngs including reinforcement, formwork, backfilling etc. as per authority requirements, specifications and drawings | C42: Lump Sum | D42: 1 | E42: 29690.467 | F42: =$D42*E42 -> 29690.467
B43: Backdrops
...

Sheet AL Dhaher-Bill 03
B5: Bill No.3, Electrical Works
A6: Sl.No | B6: Description | C6: UNIT | D6: Quantity (Q) | E6: Unit Rate AED (A) | F6: Total Line Costs Ecxluding VAT B= AED (Q X A)
B7: Electrical
B8: LV Cable
A9: 3.001 | B9: Supply of LV Cables as per drawings and specifications | C9: Lump Sum | D9: 1 | E9: 25880.109 | F9: =$D9*E9 -> 25880.109
A10: 3.002 | B10: Installation of LV Cables as per drawings and specifications | C10: Lump Sum | D10: 1 | E10: 15528.065 | F10: =$D10*E10 -> 15528.065
B11: CAT 6 Cables
A12: 3.003 | B12: Supply of CAT 6 Cables as per drawings and specifications | C12: Lump Sum | D12: 1 | E12: 14762.559 | F12: =$D12*E12 -> 14762.559
A13: 3.004 | B13: Installation OF CAT 6 Cables as per drawings and specifications | C13: Lump Sum | D13: 1 | E13: 4758.2679 | F13: =$D13*E13 -> 4758.2679
B14: FOC Cables
A15: 3.005 | B15: Supply of FOC Cables as per drawings and specifications | C15: Lump Sum | D15: 1 | E15: 14762.559 | F15: =$D15*E15 -> 14762.559
A16: 3.006 | B16: Installation OF FOC Cables as per drawings and specifications | C16: Lump Sum | D16: 1 | E16: 3172.1786 | F16: =$D16*E16 -> 3172.1786
B17: uPVC Ducts
A18: 3.007 | B18: Supply of uPVC ducts including , end caps, draw ropes, aluminium duct marker, warning tapes, cable tiles etc;complete; as per drawings, specification and authority requirement | C18: Lump Sum | D18: 1 | E18: 41827.249 | F18: =$D18*E18 -> 41827.249
A19: 3.008 | B19: Installation of uPVC ducts including excavation, shuttering, reinforcement, concrete encasement, back filling, reinstatement, end caps, draw ropes, aluminium duct marker, warning tapes, cable tiles etc;complete; as per drawings, specification and authority requirement | C19: Lump Sum | D19: 1 | E19: 17567.445 | F19: =$D19*E19 -> 17567.445
B20: Road Crossing uPVC Ducts for LV, FOC & CAT Cables
A21: 3.009 | B21: Supply of uPVC ducts complete; as per drawings, specification and authority requirement | C21: Lump Sum | D21: 1 | E21: 20913.625 | F21: =$D21*E21 -> 20913.625
A22: 3.01 | B22: Installation of uPVC ducts including excavation, shuttering, reinforcement, concrete encasement, back filling, reinstatement, end caps, draw ropes, aluminium duct marker, warning tapes, cable tiles etc;complete; as per drawings, specification and authority requirement | C22: Lump Sum | D22: 1 | E22: 7528.9049 | F22: =$D22*E22 -> 7528.9049
B23: Manholes
A24: 3.011 | B24: Manholes including excavation, backfilling, concrete works, blinding and screeds connection joints and protection coating to all internal concrete surfaces, waterproofing, cover & frame, complete in all respect as detailed on drawing and as per specification | C24: Lump Sum | D24: 1 | E24: 101054.63 | F24: =$D24*E24 -> 101054.63
B25: Main Distribution Board (MDB)
A26: 3.012 | B26: Supply, Main Distribution Board(MDB) complete including enclosure, bus bars, circuit breakers, and insulators, complete all as specified and as shown on drawings. | C26: Lump Sum | D26: 1 | E26: 541293.81 | F26: =$D26*E26 -> 541293.81
A27: 3.013 | B27: Installed, connected, and tested, complete including enclosure, bus bars, circuit breakers, and insulators,complete all as specified and as shown on drawings. | D27: 1 | E27: 24604.264 | F27: =$D27*E27 -> 24604.264
B28: Distribution Board(DB)
A29: 3.014 | B29: Supply, Distribution board complete including enclosure, bus bars, circuit breakers, and insulators, etc... complete all as specified and as shown on drawings. | C29: Lump Sum | D29: 1 | E29: 49208.528 | F29: =$D29*E29 -> 49208.528
A30: 3.015 | B30: Install, Distribution board connected, and tested, complete including enclosure, bus bars, circuit breakers, and insulators, etc... complete all as specified and as shown on drawings. | C30: Lump Sum | D30: 1 | E30: 12302.132 | F30: =$D30*E30 -> 12302.132
B31: Single Pole and Neutral (SPN) Isolator 20A
A32: 3.016 | B32: Supply, Single Pole and Neutral (SPN) Isolator 20A complete all as specified and as shown on drawings. | C32: Lump Sum | D32: 1 | E32: 1505.781 | F32: =$D32*E32 -> 1505.781
A33: 3.017 | B33: Install, connected, and tested, Single Pole and Neutral (SPN) Isolator 20A complete all as specified and as shown on drawings. | C33: Lump Sum | D33: 1 | E33: 903.46858 | F33: =$D33*E33 -> 903.46858
B34: Capacitor Bank 12.5 KVAR
A35: 3.018 | B35: Supply, Capacitor Bank 12.5 KVAR complete all as specified and as shown on drawings. | C35: Lump Sum | D35: 1 | E35: 49208.528 | F35: =$D35*E35 -> 49208.528
A36: 3.019 | B36: Install, connected, and tested, Capacitor Bank 12.5 KVAR complete all as specified and as shown on drawings. | C36: Lump Sum | D36: 1 | E36: 9841.7057 | F36: =$D36*E36 -> 9841.7057
B37: Electrical Meter IP55 Metal Case Meter Enclosure Recessed on wall
A38: 3.02 | B38: Supply, Electrical Meter 83A IP55 Metal Case Meter Enclosure Recessed on wall complete all as specified and as shown on drawings. | C38: Lump Sum | D38: 1 | E38: 9841.7057 | F38: =$D38*E38 -> 9841.7057
A39: 3.021 | B39: Install, connected, and tested, Electrical Meter 83A IP55 Metal Case Meter Enclosure Recessed on wall complete all as specified and as shown on drawings. | C39: Lump Sum | D39: 1 | E39: 2460.4264 | F39: =$D39*E39 -> 2460.4264
B40: LED SCREEN
A41: 3.022 | B41: Supply, LED SCREEN complete all as specified and as shown on drawings. | C41: Lump Sum | D41: 1 | E41: 9841.7057 | F41: =$D41*E41 -> 9841.7057
A42: 3.023 | B42: Install, connected, and tested, LED SCREEN complete all as specified and as shown on drawings. | C42: Lump Sum | D42: 1 | E42: 1279.9138 | F42: =$D42*E42 -> 1279.9138
B43: Telecommunication System
A44: 3.024 | B44: Supply UPVC ducts complete; as per drawings, specification and authority requirement | C44: Lump Sum | D44: 1 | E44: 3178.8709 | F44: =$D44*E44 -> 3178.8709
...

Sheet AL Dhaher-Bill 04
B5: Bill No.4, CONSTRUCTION OF PIPELINES
A6: Sl.No | B6: Description | C6: UNIT | D6: Quantity (Q) | E6: Unit Rate AED (A) | F6: Total Line Costs Ecxluding VAT B= AED (Q X A)
B7: Construction of uPVC Pipeline
B8: Construct Upvc pipeline as specified complete include installation of detectable warning tapes and other accessories as per specification. Rates shall include all costs for commissioning and handing over in full commercial operation. For the following pipelines
B9: Upvc pipe line
A10: 4.001 | B10: Upvc pipe line for Storm Water Works | C10: Lump Sum | D10: 1 | E10: 1169.356 | F10: =$D10*E10 -> 1169.356
A11: 4.002 | B11: Upvc pipe line for Sewer Works | C11: Lump Sum | D11: 1 | E11: 848.12946 | F11: =$D11*E11 -> 848.12946
B12: DI Pipelines
B13: Construct the Ductile Iron (D.I) pipeline as per the approved specifications, including tie-in connection with the existing line using polyethylene sleeves and rubber gaskets, installation of detectable warning tapes, and all necessary accessories. The scope includes supply of all materials, labor, equipment, and consumables required for the complete installation, as well as testing for pressure and leakage, flushing, disinfection, commissioning, and handing over the system in full commercial operation. The quoted rates shall cover all associated costs to deliver a fully functional and operational pipeline in compliance with relevant standards and project requirements.
A14: 4.003 | B14: DI Pipelines | C14: Lump Sum | D14: 1 | E14: 22044.479 | F14: =$D14*E14 -> 22044.479
B15: Construction of PPR Pipeline
B16: Construct PPR pipeline using butt fusion method as specified complete include installation of detectable warning tapes and other accessories as per specification. Rates shall include all costs for testing, flushing, disinfection, commissioning and handing over in full commercial operation.
A17: 4.004 | B17: PPR pipe line | C17: Lump Sum | D17: 1 | E17: 809.21339 | F17: =$D17*E17 -> 809.21339
B18: Construction of HDPE Pipeline
B19: Construct the HDPE pipeline using the butt fusion method as per the approved specifications, complete with tie-in connections, installation of detectable warning tapes, and all necessary accessories. The scope shall include supply of all materials, equipment, and labor required for the complete installation. Rates shall cover all associated costs for testing, flushing, disinfection, commissioning, and handing over the system in full commercial operation, in compliance with project and industry standards.
B20: HDPE pipeline
A21: 4.005 | B21: HDPE pipeline | C21: Lump Sum | D21: 1 | E21: 19122.374 | F21: =$D21*E21 -> 19122.374
B22: Exta over item For pipeline construction items for installation of D.I, PPR, HDPE & uPVC fittings complete (such as restrained couplings, bends, tees, reducers, reducing flanges, Lange spigot pieces, flange socket pieces, quick dismantling joints, flanged adaptors, socket connectors, tied dismantling joints, blank flanges, double flanged extension pieces, adjustable S bends, duck foot elbows, flanged pipe pieces with anchor flange, transition pieces, collars, stepped couplings, and caps, restraining glands, etc.) for the following pipes:
B23: uPVC Fittings
A24: 4.006 | B24: uPVC pipe line for Storm Water Works | C24: Lump Sum | D24: 1 | E24: 1595.5389 | F24: =$D24*E24 -> 1595.5389
A25: 4.007 | B25: uPVC pipe line for Sewerage Works | C25: Lump Sum | D25: 1 | E25: 1060.1568 | F25: =$D25*E25 -> 1060.1568
B26: DI Pipelines
A27: 4.008 | B27: DI Pipelines | C27: Lump Sum | D27: 1 | E27: 13020.02 | F27: =$D27*E27 -> 13020.02
B28: PPR Pipelines
A29: 4.009 | B29: PPR Pipelines | C29: Lump Sum | D29: 1 | E29: 1650.6371 | F29: =$D29*E29 -> 1650.6371
B30: HDPE pipeline
A31: 4.01 | B31: HDPE pipeline | C31: Lump Sum | D31: 1 | E31: 15942.714 | F31: =$D31*E31 -> 15942.714
B32: Exta over item for pipeline construction for installation of flanged valves, gate valves, flowmeters, control valves, etc. including all the accessories as per the specification.
A33: 4.011 | B33: Flow Meter Validation Unit | C33: Lump Sum | D33: 1 | E33: 37477.215 | F33: =$D33*E33 -> 37477.215
A34: 4.012 | B34: Settlement Type Electromagnetic Flow Meter | C34: Lump Sum | D34: 1 | E34: 29943.291 | F34: =$D34*E34 -> 29943.291
A35: 4.013 | B35: Control Valve | C35: Lump Sum | D35: 1 | E35: 24146.729 | F35: =$D35*E35 -> 24146.729
A36: 4.014 | B36: Air Valve | C36: Lump Sum | D36: 1 | E36: 2161.2908 | F36: =$D36*E36 -> 2161.2908
A37: 4.015 | B37: Washout Valve | C37: Lump Sum | D37: 1 | E37: 6148.6305 | F37: =$D37*E37 -> 6148.6305
A38: 4.016 | B38: Manual Butterfly Valve | C38: Lump Sum | D38: 1 | E38: 6865.1172 | F38: =$D38*E38 -> 6865.1172
A39: 4.017 | B39: Manual Check Valve | C39: Lump Sum | D39: 1 | E39: 7070.0557 | F39: =$D39*E39 -> 7070.0557
A40: 4.018 | B40: Electromagnetic Flow Meter | C40: Lump Sum | D40: 1 | E40: 160584.42 | F40: =$D40*E40 -> 160584.42
A41: 4.019 | B41: Gate Valve | C41: Lump Sum | D41: 1 | E41: 2540.7902 | F41: =$D41*E41 -> 2540.7902
B42: Service Connections
B43: Installation of Pipework for Service Connections
B44: Construct of New Tapping : Work includes Hand excavation, dewatring,and installation of new saddle strap & ferrule/pressure tapping tee with extra long outlet with all required fittings and supply of installation of moulding compound warping tap & polythene sleeve for protection of saddle & ferrule,backfilling and shutdown of distribution etc.all as per TAQA Specification.
...

Sheet AL Dhaher-Bill 05
B5: Bill No.5, INSTRUMENTATION AND CONTROL/ SCADA
A6: Sl.No | B6: Description | C6: UNIT | D6: Quantity (Q) | E6: Unit Rate AED (A) | F6: Total Line Costs Ecxluding VAT B= AED (Q X A)
B7: TANKER CONTROL SYSTEM/WorkStation
B8: CONTROL SYSTEM
A9: 5.001 | B9: Dual system servers including but not limited to, CPU, HDD, keyboard mouse, DVDD, USB drive, software interface devices. | C9: No | D9: 1 | E9: 124949.7 | F9: =$D9*E9 -> 124949.7
A10: 5.002 | B10: Operator workstation including but not limited to, two computers each 21" LCD monitor, CPU, keyboard, mouse, interface devices, 2 GB RAM min., HDD, USB drive, DVDD etc. including one printer. | C10: No | D10: 1 | E10: 40667.798 | F10: =$D10*E10 -> 40667.798
A11: 5.003 | B11: Electronic cabinets including but not limited to, one dual redundant, PLC, communication and power supply modules, interface/signal/alarm etc. modules alongwith suitable communication equipment. | C11: No | D11: 1 | E11: 531639.39 | F11: =$D11*E11 -> 531639.39
A12: 5.004 | B12: Redundant secured communication network, bus and interfaces and other auxiliaries, as required | C12: Lump Sum | D12: 1 | E12: 147036.17 | F12: =$D12*E12 -> 147036.17
A13: 5.005 | B13: Software packages including but not limited to the original license including all application, engineering and HMI software, configuration software etc., as required. | C13: Lump Sum | D13: 1 | E13: 446271.65 | F13: =$D13*E13 -> 446271.65
A14: 5.006 | B14: Field Process Unit, which consists of flow computer with card reader, push buttons for Start / Stop, Emergency push button, lamps for indication, remote I/O module/ RTU | C14: No | D14: 8 | E14: 181627.3 | F14: =$D14*E14 -> 1453018.4
A15: 5.007 | B15: Start / Stop Panel for Manual Tanker Filling Operation as specified | C15: No | D15: 8 | E15: 3588.778 | F15: =$D15*E15 -> 28710.224
A16: 5.008 | B16: Fiscal Ticket Printers for printing the prepaid cards etc. as required showing tanker information , volume and amount. To be installed in Customer Service Unit of the office building | C16: No | D16: 2 | E16: 29513.307 | F16: =$D16*E16 -> 59026.614
A17: 5.009 | B17: Supply and Install A3 & A4 printer | C17: Lump Sum | D17: 1 | E17: 7968.9275 | F17: =$D17*E17 -> 7968.9275
A18: 5.01 | B18: Supply and Install UPS as required | C18: Lump Sum | D18: 1 | E18: 119528.89 | F18: =$D18*E18 -> 119528.89
B19: LEVEL SWITCHES
A20: 5.011 | B20: Supply of level switches of suitable type for tanker overflow detection complete with cable and other installation accessories to be installed on the filling hose. | C20: No. | D20: 8 | E20: 14221.265 | F20: =$D20*E20 -> 113770.12
A21: 5.012 | B21: ACCESS CONTROL SYSTEM
A22: 5.013 | B22: Proximity Card Reader Unit / including all accessories required for installing at the entrance of the station, complete with power supply unit, modules etc and all other accessories as required for communication to centralised loading system PLC. | C22: No | D22: 4 | E22: 99607.411 | F22: =$D22*E22 -> 398429.64
A23: 5.014 | B23: Motorised boom including warning beacons, audible alram and all other accessries, to be installed at the entrance and exit of the station as required including interfaces with the loading system PLC. | C23: No | D23: 4 | E23: 119528.89 | F23: =$D23*E23 -> 478115.57
A24: 5.015 | B24: Display units for bay identifcation and driver information including all required accessories and interfaces. | C24: No | D24: 10 | E24: 41318.63 | F24: =$D24*E24 -> 413186.3
B25: SPARE PARTS FOR ELECTRICAL EQUIPMENT
A26: 5.016 | B26: Spare parts for sub-distribution boards complete as specified. | C26: Lump Sum | D26: 1 | E26: 147566.54 | F26: =$D26*E26 -> 147566.54
B27: SPARE PARTS FOR I & C SYSTEM & F.O CABLE
B28: SPARE FOR THE FIELD INSTRUMENTS
A29: 5.017 | B29: Electromagnetic flowmeter transmitter. | C29: No | D29: 1 | E29: 64263.386 | F29: =$D29*E29 -> 64263.386
A30: 5.018 | B30: Pressure transmitter (One from each range selected) | C30: No | D30: 1 | E30: 7528.9049 | F30: =$D30*E30 -> 7528.9049
A31: 5.019 | B31: Differential pressure switch, one no. for the highest range selected. | C31: No | D31: 1 | E31: 11910.727 | F31: =$D31*E31 -> 11910.727
A32: 5.02 | B32: Pressure gauge, one no. for each range selected. | C32: No | D32: 1 | E32: 1500.7617 | F32: =$D32*E32 -> 1500.7617
A33: 5.021 | B33: Level Switches | C33: No | D33: 1 | E33: 8345.3728 | F33: =$D33*E33 -> 8345.3728
B34: SPARES FOR CONTROL AND SCADA SYSTEM
A35: 5.022 | B35: The number of spare equipment modules shall be 5% of the installed units, rounded upto the nearest integer i.e. CPU, CP, power supply modules, I/O modules of each type, bus controller, fibre optic interfaace modules, all communication device and modules etc. alongwith 10% spare hardware accessories like relays, batteries, MCB's, etc, and EPROM/EEPROM shall be 2 minimum of each type. | C35: Lump Sum | D35: 1 | E35: 250863.11 | F35: =$D35*E35 -> 250863.11
B36: SPARE FOR F.O. CABLE SYSTEM
A37: 5.023 | B37: Fibre optical splicing kit, 1 set for tap off location. | C37: Lump Sum | D37: 1 | E37: 103296.57 | F37: =$D37*E37 -> 103296.57
A38: 5.024 | B38: 10% minimum F.O. interfacing module/component of each type installed at the F.O. system cabinet/panel including interfacing module, power supply module, patch panel etc. | C38: Lump Sum | D38: 1 | E38: 44269.961 | F38: =$D38*E38 -> 44269.961
A39: 5.025 | B39: Recommended consumables for 2 years trouble free operation | C39: Lump Sum | D39: 1 | E39: 44269.961 | F39: =$D39*E39 -> 44269.961
A40: 5.026 | B40: SCADA System Integration with existing main SCADA and Customer care and Billing System ( CC&B) | C40: Lump Sum | D40: 1 | E40: 49208.528 | F40: =$D40*E40 -> 49208.528
B41: Total Costs for Bill No.5 excluding VAT (AED) | F41: =SUM(F9:F40) -> 5095343.2

Sheet Nahel-Summary 
B5: SUMMARY SHEET - NAHEL
A6: Bill No. | B6: Description | C6: Total Costs Excluding VAT (AED)
A7: 1 | B7: SUPPLY OF PIPEWORKS | C7: ='Nahel-Bill 01'!F43 -> 879340.36
A8: 2 | B8: CIVIL WORKS | C8: ='Nahel-Bill 02'!F110 -> 5703759
A9: 3 | B9: ELECTRICAL WORKS | C9: ='Nahel-Bill 03'!F86 -> 2206138.9
A10: 4 | B10: CONSTRUCTION OF PIPELINES | C10: ='Nahel-Bill 04'!F42 -> 566575.37
A11: 5 | B11: INSTRUMENTATION AND CONTROL/ SCADA | C11: ='Nahel-Bill 05'!F41 -> 5119917.6
B13: Total Costs Excluding VAT ( AED) | C13: =SUM(C7:C11) -> 14475731
B14: Total Value Added Tax (VAT/5%) (AED) | C14: =C13*0.05 -> 723786.56
B15: Total Costs Including VAT (AED) | C15: =SUM(C13:C14) -> 15199518
B18: Total Costs in Words Excluding VAT (AED): | C18: Dirhams Fourteen million, four hundred seventy-five thousand, seven hundred thirty-one and fourteen Fils
B19: VAT Amount in Words (AED): | C19: Dirhams Seven hundred twenty-three thousand, seven hundred eighty-six and fifty-six Fils
B20: Total Costs in Words Including VAT (AED): | C20: Dirhams Fifteen million, one hundred ninety-nine thousand, five hundred seventeen and seventy Fils

Sheet Nahel-Bill 01
B5: Bill No.1, SUPPLY OF PIPEWORKS
A6: Sl.No | B6: Description | C6: UNIT | D6: Quantity (Q) | E6: Unit Rate AED (A) | F6: Total Line Costs Ecxluding VAT B= AED (Q X A)
B7: Storm Water Works
A8: 1.001 | B8: Supply the following ISO standard uPVC including warning tape and all other accessories as per ADEWA standard specifications | C8: Lump Sum | D8: 1 | E8: 1033.1906 | F8: =$D8*E8 -> 1033.1906
B9: Sewerage Works
A10: 1.002 | B10: Supply the following ISO standard uPVC including warning tape and all other accessories as per ADEWA standard specifications | C10: Lump Sum | D10: 1 | E10: 3220.4542 | F10: =$D10*E10 -> 3220.4542
B11: Gully Trap
A12: 1.003 | B12: Supply the following ISO standard Gully trap including all other accessories as per ADEWA standard specifications | C12: Lump Sum | D12: 1 | E12: 225.86715 | F12: =$D12*E12 -> 225.86715
B13: Potable Water Works
B14: Ductile Iron (DI) Pipe
B15: Supply and Install DI pipe as specified complete with installation of detectable warning tapes and other accessories all in accordance with TAQA standard specification, data sheet and drawings.
A16: 1.004 | B16: DI - Standard Socket Spigot pipes | C16: Lump Sum | D16: 1 | E16: 115080.92 | F16: =$D16*E16 -> 115080.92
A17: 1.004a | B17: DI - Restrained | C17: Lump Sum | D17: 1 | E17: 115080.92 | F17: =$D17*E17 -> 115080.92
B18: Gate Valves
A19: =MAX(A12:A17)+0.001 -> 1.005 | B19: Supply of PN 16 Manual Gate Valves above ground in accordance with specification, drawings and data sheet. | C19: Lump Sum | D19: 1 | E19: 7077.1706 | F19: =$D19*E19 -> 7077.1706
B20: Air Valves
A21: =MAX(A14:A19)+0.001 -> 1.006 | B21: Supply of Air Valves in accordance with specification, drawings and data sheet. | C21: Lump Sum | D21: 1 | E21: 4111.4868 | F21: =$D21*E21 -> 4111.4868
B22: Bulk Connection Chamber Valves & Fittings
A23: =MAX(A16:A21)+0.001 -> 1.007 | B23: Supply of Manual Check Valves & Fittings in accordance with specification, drawings and data sheet. | C23: Lump Sum | D23: 1 | E23: 18387.202 | F23: =$D23*E23 -> 18387.202
A24: =MAX(A17:A22)+0.001 -> 1.007 | B24: Supply of Manual Butterfly Valves & Fittings in accordance with specification, drawings and data sheet. | C24: Lump Sum | D24: 1 | E24: 10817.711 | F24: =$D24*E24 -> 10817.711
A25: =MAX(A18:A23)+0.001 -> 1.008 | B25: Supply of Settlement Type Electromagnetic Flow Meter & Fittings on 400mm dia line in accordance with specification, drawings and data sheet. | C25: Lump Sum | D25: 1 | E25: 71090.853 | F25: =$D25*E25 -> 71090.853
A26: =MAX(A19:A24)+0.001 -> 1.008 | B26: Supply of Control Valve & Fittings in accordance with specification, drawings and data sheet. | C26: Lump Sum | D26: 1 | E26: 80331.644 | F26: =$D26*E26 -> 80331.644
B27: Wash Out Valves
A28: =MAX(A21:A26)+0.001 -> 1.009 | B28: Supply of Wash Out Valves in accordance with specification, drawings and data sheet. | C28: Lump Sum | D28: 1 | E28: 9939.3994 | F28: =$D28*E28 -> 9939.3994
B29: BIP TAP
A30: =MAX(A23:A28)+0.001 -> 1.01 | B30: Supply of BIP TAP including all fittings and accessories | C30: Lump Sum | D30: 1 | E30: 451.73429 | F30: =$D30*E30 -> 451.73429
B31: Flow Meter Validation Unit
A32: =MAX(A25:A30)+0.001 -> 1.011 | B32: Supply flow meter validation unit with validation software all as per specifications. The unit shall be supplied with power supply with rechargeable batteries and integral charger unit. | C32: Lump Sum | D32: 1 | E32: 32123.327 | F32: =$D32*E32 -> 32123.327
B33: Flow Control Valve
A34: 1.011a | B34: Supply a flow control valve for the above-ground (vertical pipeline) validation unit, complete with validation software, in full compliance with the project specifications. The unit shall include a power supply with rechargeable batteries and an integral charging unit, ensuring continuous and reliable operation. All components shall be suitable for the intended application and delivered ready for installation and commissioning. | C34: Lump Sum | D34: 1 | E34: 80473.188 | F34: =$D34*E34 -> 80473.188
B35: Electromagnetic Flow Meter
A36: =MAX(A29:A34)+0.001 -> 1.012 | B36: Supply of 6" flow meter. all in accordance with specification, data sheet and drawings. | C36: Lump Sum | D36: 1 | E36: 296240.52 | F36: =$D36*E36 -> 296240.52
B37: PPR Pipes
A38: =MAX(A31:A36)+0.001 -> 1.013 | B38: Supply , PPR 20-25mm pipes Including valves and chambers all as specified and shown on drawings. | C38: Lump Sum | D38: 1 | E38: 2679.1878 | F38: =$D38*E38 -> 2679.1878
A39: =MAX(A32:A37)+0.001 -> 1.013 | B39: Supply of PN 16 Flexible hoses of sufficient length, with one end flanged and necessary attachments including fasteners, gaskets etc. for filling bays as specified. | C39: Lump Sum | D39: 1 | E39: 17935.524 | F39: =$D39*E39 -> 17935.524
B40: Domestic water pump set
B41: Domestic water pump set for building, with single stage pumps and pressure vessel as shown on drawings, control box, skid mounted, installed, connected and tested complete with stainless steel headers, pump individual isolating ball valves, check valves, isolating butterfly valves PN 20, lug and wafer type lever operated, strainer cast iron body PN 20, flexible connections, concrete inertia pad, house pad, vibration eliminator pad, low level control float switches, pressure switch and controls all supplied from pump manufacturer diaphragm tank (s), food quality synthetic rubber membrane, steel painted body, working pressure 2 bars with isolating valve and pressure gauge, electric connections, wiring and accessories all as specified and shown on the drawings.
A42: =MAX(A35:A40)+0.001 -> 1.014 | B42: Water Pump set 1 duty + 1 standby 1.0 L/S @30m head each pump | C42: Lump Sum | D42: 1 | E42: 13040.063 | F42: =$D42*E42 -> 13040.063
B43: Total Costs for Bill No.1 excluding VAT (AED) | F43: =SUM(F8:F42) -> 879340.36

Sheet Nahel-Bill 02
B5: Bill No.2, CIVIL WORKS
A6: Sl.No | B6: Description | C6: UNIT | D6: Quantity (Q) | E6: Unit Rate AED (A) | F6: Total Line Costs Ecxluding VAT B= AED (Q X A)
B7: Trial trench and Trial pits
A8: 2.001 | B8: Trial trench and Trial pits | C8: Lump Sum | D8: 1 | E8: 8678.3177 | F8: =$D8*E8 -> 8678.3177
B9: Trenches for Pipelines
B10: Excavate, dewater and backfill trenches for pipelines including shoring, surveying, etc. for a maximum cover to pipelines of 1.2 m as per specification and as shown in drawings for the following sizes of pipelines
B11: PPR Pipelines
A12: 2.002 | B12: PPR Pipelines | C12: Lump Sum | D12: 1 | E12: 6175.6703 | F12: =$D12*E12 -> 6175.6703
B13: DI Pipelines
A14: 2.003 | B14: DI Pipelines | C14: Lump Sum | D14: 1 | E14: 192641.55 | F14: =$D14*E14 -> 192641.55
B15: uPVC Pipelines for Storm Water Works
A16: 2.004 | B16: uPVC Pipelines | C16: Lump Sum | D16: 1 | E16: 7430.4878 | F16: =$D16*E16 -> 7430.4878
B17: uPVC Pipelines for Sewerage Works
A18: 2.004a | B18: uPVC Pipelines | C18: Lump Sum | D18: 1 | E18: 41561.523 | F18: =$D18*E18 -> 41561.523
B19: E.O.I for Excavate and Backfill Trenches for Pipelines
B20: E.O.I. for excavation of every additional 500 mm excavation depth exceeding 1.2 m cover, including dewatering, shoring, backfilling and disposal of surplus material all as per specification for the following pipelines
B21: PPR Pipelines
A22: 2.005 | B22: PPR Pipelines | C22: Lump Sum | D22: 1 | E22: 4920.8528 | F22: =$D22*E22 -> 4920.8528
B23: DI Pipelines
A24: 2.006 | B24: DI Pipelines | C24: Lump Sum | D24: 1 | E24: 4920.8528 | F24: =$D24*E24 -> 4920.8528
B25: uPVC Pipelines for Storm Water Works
A26: 2.007 | B26: uPVC Pipelines | C26: Lump Sum | D26: 1 | E26: 4920.8528 | F26: =$D26*E26 -> 4920.8528
B27: uPVC Pipelines for Sewerage Works
A28: 2.007a | B28: uPVC Pipelines | C28: Lump Sum | D28: 1 | E28: 4920.8528 | F28: =$D28*E28 -> 4920.8528
A29: 2.008 | B29: E.O.I for excavation in rock using rock breaker including disposal of excavated material as per the Municipality requirements - the rock should be classified as per specs by lab test | C29: Lump Sum | D29: 1 | E29: 4920.8528 | F29: =$D29*E29 -> 4920.8528
A30: 2.009 | B30: E.O.I. for supply, place and compact aPPRoved imported bedding / fill material/gatch including disposal of surplus material as per specifications and as ordered and authorized by TAQA Engineer | C30: Lump Sum | D30: 1 | E30: 4920.8528 | F30: =$D30*E30 -> 4920.8528
A31: 2.01 | B31: General excavation for any other purpose including dewatering, backfilling as required or instructed by TAQA Engineer. | C31: Lump Sum | D31: 1 | E31: 22607.382 | F31: =$D31*E31 -> 22607.382
B32: Construction of Manholes and Facilities at Pipelines for Storm Water Works
A33: 2.011 | B33: Manholes including excavation, dewatering, shoring, backfilling, concrete works including the Removable cover slab, benching, blinding and screeds connection joints and protection coating to all internal concrete surfaces, waterproofing , tanking , heavy duty ductile cover & frame, complete in all respect as detailed on drawing and as per specification | C33: Lump Sum | D33: 1 | E33: 66775.973 | F33: =$D33*E33 -> 66775.973
A34: 2.012 | B34: Construction Storm water channels excavation, dewatering, shoring, backfilling, concrete works including the gratings complete in all respect as detailed on drawing and as per specification | C34: Lump Sum | D34: 1 | E34: 179942.71 | F34: =$D34*E34 -> 179942.71
B35: Backdrops
A36: 2.013 | B36: Construction of Backdrop complete with concrete surround as per SWS standard drawing | C36: Lump Sum | D36: 1 | E36: 21651.753 | F36: =$D36*E36 -> 21651.753
B37: Soakaway
A38: 2.014 | B38: Construction of Soakaway complete with concrete surround as per SWS standard drawing | C38: Lump Sum | D38: 1 | E38: 18374.465 | F38: =$D38*E38 -> 18374.465
B39: Proposed Road Crossing Ducts
A40: 2.014a | B40: Supply and installation of HDPE ducts for road crossing, including reinforced concrete surround and all associated works such as excavation, duct laying, concrete casting, backfilling, compaction, and testing, all as per drawings and specifications | C40: Lump Sum | D40: 1 | E40: 63577.419 | F40: =$D40*E40 -> 63577.419
B41: Construction of Chambers, and Facilities at Pipelines
B42: Construction of Concrete Chambers
B43: Construct reinforced concrete chambers, as per TAQA's standard specification with precast cover slab for chambers on pipelines including the supply of all materials complete with protection board and water proofing of outside walls from top to bottom water stop at construction joints, installation of hot dipped galvanized lifting hooks in cover slab, supports for valve spindle extension casting in of anchor flange sealing flange (water stop),access cover frame, surface box, chamber indication plate owner information plate ventilation pipes bolting of aluminum ladder excavation dewatering, backfilling, etc., all as per specification and as shown on tender drawings (for lifting hooks, ladder, vent pipes, chamber protection & water stop) all as directed and authorized by TAQA Engineer (not include supply of pipework inside chambers)
A44: 2.015 | B44: Gate Valve Chamber (s) as per Drawing | C44: Lump Sum | D44: 1 | E44: 66923.599 | F44: =$D44*E44 -> 66923.599
...

Sheet Nahel-Bill 03
B5: Bill No.3, Electrical Works
A6: Sl.No | B6: Description | C6: UNIT | D6: Quantity (Q) | E6: Unit Rate AED (A) | F6: Total Line Costs Ecxluding VAT B= AED (Q X A)
B7: Electrical
B8: LV Cable
A9: 3.001 | B9: Supply of LV Cables as per drawings and required specifications | C9: Lump Sum | D9: 1 | E9: 26342.802 | F9: =$D9*E9 -> 26342.802
A10: 3.002 | B10: Installation of LV Cables as per drawings and required specifications | C10: Lump Sum | D10: 1 | E10: 15805.681 | F10: =$D10*E10 -> 15805.681
A11: 3.003 | B11: Supply of CAT 6 Cables as per drawings and required specifications | C11: Lump Sum | D11: 1 | E11: 14762.559 | F11: =$D11*E11 -> 14762.559
A12: 3.004 | B12: Installation OF CAT 6 Cables as per drawings and required specifications | C12: Lump Sum | D12: 1 | E12: 3802.5989 | F12: =$D12*E12 -> 3802.5989
B13: FOC Cables
A14: 3.005 | B14: Supply of FOC Cables as per drawings and required specifications | C14: Lump Sum | D14: 1 | E14: 24604.264 | F14: =$D14*E14 -> 24604.264
A15: 3.006 | B15: Installation OF FOC Cables as per drawings and required specifications | C15: Lump Sum | D15: 1 | E15: 9841.7057 | F15: =$D15*E15 -> 9841.7057
B16: uPVC Ducts
A17: 3.007 | B17: Supply of uPVC ducts including , end caps, draw ropes, aluminium duct marker, warning tapes, cable tiles etc;complete; as per drawings, specification and authority requirement | C17: Lump Sum | D17: 1 | E17: 6337.6648 | F17: =$D17*E17 -> 6337.6648
A18: 3.008 | B18: Installation of uPVC ducts including excavation, shuttering, reinforcement, concrete encasement, back filling, reinstatement, end caps, draw ropes, aluminium duct marker, warning tapes, cable tiles etc;complete; as per drawings, specification and authority requirement | C18: Lump Sum | D18: 1 | E18: 3802.5989 | F18: =$D18*E18 -> 3802.5989
B19: Road Crossing uPVC Ducts for LV, FOC & CAT Cables
A20: 3.009 | B20: Supply of uPVC ducts complete; as per drawings, specification and authority requirement | C20: Lump Sum | D20: 1 | E20: 6337.6648 | F20: =$D20*E20 -> 6337.6648
A21: 3.01 | B21: Installation of uPVC ducts including excavation, shuttering, reinforcement, concrete encasement, back filling, reinstatement, end caps, draw ropes, aluminium duct marker, warning tapes, cable tiles etc;complete; as per drawings, specification and authority requirement | C21: Lump Sum | D21: 1 | E21: 3802.5989 | F21: =$D21*E21 -> 3802.5989
B22: Manholes
A23: 3.011 | B23: Manholes including excavation, backfilling, concrete works, blinding and screeds connection joints and protection coating to all internal concrete surfaces, waterproofing, cover & frame, complete in all respect as detailed on drawing and as per specification | C23: Lump Sum | D23: 1 | E23: 108545.06 | F23: =$D23*E23 -> 108545.06
B24: Main Distribution Board (MDB)
A25: 3.012 | B25: Supply, Main Distribution Board(MDB) complete including enclosure, bus bars, circuit breakers, and insulators, complete all as specified and as shown on drawings. | C25: Lump Sum | D25: 1 | E25: 541293.81 | F25: =$D25*E25 -> 541293.81
A26: 3.013 | B26: Installed, connected, and tested, complete including enclosure, bus bars, circuit breakers, and insulators,complete all as specified and as shown on drawings. | C26: Lump Sum | D26: 1 | E26: 49208.528 | F26: =$D26*E26 -> 49208.528
B27: Distribution Board(DB)
A28: 3.014 | B28: Supply, Distribution board complete including enclosure, bus bars, circuit breakers, and insulators, complete all as specified and as shown on drawings. | C28: Lump Sum | D28: 1 | E28: 24604.264 | F28: =$D28*E28 -> 24604.264
A29: 3.015 | B29: Install, Distribution board connected, and tested, complete including enclosure, bus bars, circuit breakers, and insulators,complete all as specified and as shown on drawings. | C29: Lump Sum | D29: 1 | E29: 7381.2793 | F29: =$D29*E29 -> 7381.2793
B30: Single Pole and Neutral (SPN) Isolator 20A
A31: 3.016 | B31: Supply, Single Pole and Neutral (SPN) Isolator 20A complete all as specified and as shown on drawings. | C31: Lump Sum | D31: 1 | E31: 9841.7057 | F31: =$D31*E31 -> 9841.7057
A32: 3.017 | B32: Install, connected, and tested, Single Pole and Neutral (SPN) Isolator 20A complete all as specified and as shown on drawings. | C32: Lump Sum | D32: 1 | E32: 2460.4264 | F32: =$D32*E32 -> 2460.4264
B33: Capacitor Bank 12.5 KVAR
A34: 3.018 | B34: Supply, Capacitor Bank 12.5 KVAR complete all as specified and as shown on drawings. | C34: Lump Sum | D34: 1 | E34: 49208.528 | F34: =$D34*E34 -> 49208.528
A35: 3.019 | B35: Install, connected, and tested, Capacitor Bank 12.5 KVAR complete all as specified and as shown on drawings. | C35: Lump Sum | D35: 1 | E35: 9841.7057 | F35: =$D35*E35 -> 9841.7057
B36: Electrical Meter IP55 Metal Case Meter Enclosure Recessed on wall
A37: 3.02 | B37: Supply, Electrical Meter 83A IP55 Metal Case Meter Enclosure Recessed on wall complete all as specified and as shown on drawings. | C37: Lump Sum | D37: 1 | E37: 9841.7057 | F37: =$D37*E37 -> 9841.7057
A38: 3.021 | B38: Install, connected, and tested, Electrical Meter 83A IP55 Metal Case Meter Enclosure Recessed on wall complete all as specified and as shown on drawings. | C38: Lump Sum | D38: 1 | E38: 2460.4264 | F38: =$D38*E38 -> 2460.4264
B39: LED SCREEN including Foundation
A40: 3.022 | B40: Supply, LED SCREEN complete all as specified and as shown on drawings. | C40: Lump Sum | D40: 1 | E40: 9841.7057 | F40: =$D40*E40 -> 9841.7057
A41: 3.023 | B41: Install, connected, and tested, LED SCREEN complete all as specified and as shown on drawings. | C41: Lump Sum | D41: 1 | E41: 1279.9138 | F41: =$D41*E41 -> 1279.9138
B42: Telecommunication System
A43: 3.024 | B43: Supply UPVC ducts complete; as per drawings, specification and authority requirement | C43: Lump Sum | D43: 1 | E43: 8173.0445 | F43: =$D43*E43 -> 8173.0445
A44: 3.025 | B44: Installation of upvc ducts including excavation, back filling, reinstatement, end caps, draw ropes, aluminium duct marker, warning tapes etc;complete; as per drawings, specification and authority requirement | C44: Lump Sum | D44: 1 | E44: 4903.8267 | F44: =$D44*E44 -> 4903.8267
...

Sheet Nahel-Bill 04
B5: Bill No.4, CONSTRUCTION OF PIPELINES
A6: Sl.No | B6: Description | C6: UNIT | D6: Quantity (Q) | E6: Unit Rate AED (A) | F6: Total Line Costs Ecxluding VAT B= AED (Q X A)
B7: A- Construction of uPVC Pipeline
B8: Construct Upvc pipeline as specified complete include installation of detectable warning tapes and other accessories as per specification. Rates shall include all costs for commissioning and handing over in full commercial operation. For the following pipelines
B9: Upvc pipe line
A10: 4.001 | B10: Upvc pipe line for Storm Water Works | C10: Lump Sum | D10: 1 | E10: 1739.3042 | F10: =$D10*E10 -> 1739.3042
A11: 4.002 | B11: Upvc pipe line for Sewer Works | C11: Lump Sum | D11: 1 | E11: 2342.326 | F11: =$D11*E11 -> 2342.326
B12: DI Pipelines
B13: Construct the Ductile Iron (D.I) pipeline as per the approved specifications, including tie-in connection with the existing line using polyethylene sleeves and rubber gaskets, installation of detectable warning tapes, and all necessary accessories. The scope includes supply of all materials, labor, equipment, and consumables required for the complete installation, as well as testing for pressure and leakage, flushing, disinfection, commissioning, and handing over the system in full commercial operation. The quoted rates shall cover all associated costs to deliver a fully functional and operational pipeline in compliance with relevant standards and project requirements.
A14: 4.003 | B14: DI Pipelines | C14: Lump Sum | D14: 1 | E14: 77938.4 | F14: =$D14*E14 -> 77938.4
B15: Construction of PPR Pipeline
B16: Construct PPR pipeline using butt fusion method as specified complete include installation of detectable warning tapes and other accessories as per specification. Rates shall include all costs for testing, flushing, disinfection, commissioning and handing over in full commercial operation.
A17: 4.004 | B17: PPR pipe line | C17: Lump Sum | D17: 1 | E17: 2455.3599 | F17: =$D17*E17 -> 2455.3599
B18: Exta over item For pipeline construction items for installation of D.I, PPR, HDPE & uPVC fittings complete (such as restrained couplings, bends, tees, reducers, reducing flanges, Lange spigot pieces, flange socket pieces, quick dismantling joints, flanged adaptors, socket connectors, tied dismantling joints, blank flanges, double flanged extension pieces, adjustable S bends, duck foot elbows, flanged pipe pieces with anchor flange, transition pieces, collars, stepped couplings, and caps, restraining glands, etc.) for the following pipes:
B19: uPVC Fittings
A20: 4.005 | B20: uPVC pipe line for Storm Water Works | C20: Lump Sum | D20: 1 | E20: 2119.7514 | F20: =$D20*E20 -> 2119.7514
A21: 4.006 | B21: uPVC pipe line for Sewerage Works | C21: Lump Sum | D21: 1 | E21: 3346.1799 | F21: =$D21*E21 -> 3346.1799
B22: DI Pipelines
A23: 4.007 | B23: DI Pipelines | C23: Lump Sum | D23: 1 | E23: 75502.823 | F23: =$D23*E23 -> 75502.823
B24: PPR Pipelines
A25: 4.008 | B25: PPR Pipelines | C25: Lump Sum | D25: 1 | E25: 2050.3517 | F25: =$D25*E25 -> 2050.3517
B26: Exta over item pipeline construction for installation of flanged valves, gate valves, flowmeters, control valves, etc. including all the accessories as per the specification.
A27: 4.009 | B27: Flow Meter Validation Unit | C27: Lump Sum | D27: 1 | E27: 37477.215 | F27: =$D27*E27 -> 37477.215
A28: 4.01 | B28: Settlement Type Electromagnetic Flow Meter | C28: Lump Sum | D28: 1 | E28: 37606.324 | F28: =$D28*E28 -> 37606.324
A29: 4.011 | B29: Control Valve Chamber | C29: Lump Sum | D29: 1 | E29: 53554.432 | F29: =$D29*E29 -> 53554.432
A30: 4.012 | B30: Air Valve | C30: Lump Sum | D30: 1 | E30: 2740.9898 | F30: =$D30*E30 -> 2740.9898
A31: 4.013 | B31: Washout Valve | C31: Lump Sum | D31: 1 | E31: 6626.2661 | F31: =$D31*E31 -> 6626.2661
A32: 4.014 | B32: Manual Butterfly Valve | C32: Lump Sum | D32: 1 | E32: 7211.8075 | F32: =$D32*E32 -> 7211.8075
A33: 4.015 | B33: Manual Check Valve | C33: Lump Sum | D33: 1 | E33: 12258.135 | F33: =$D33*E33 -> 12258.135
A34: 4.016 | B34: Electromagnetic Flow Meter | C34: Lump Sum | D34: 1 | E34: 210118.16 | F34: =$D34*E34 -> 210118.16
A35: 4.017 | B35: Gate Valve | C35: Lump Sum | D35: 1 | E35: 4718.1137 | F35: =$D35*E35 -> 4718.1137
B36: Service Connections
B37: Installation of Pipework for Service Connections
B38: Construct of New Tapping : Work includes Hand excavation, dewatring,and installation of new saddle strap & ferrule/pressure tapping tee with extra long outlet with all required fittings and supply of installation of moulding compound warping tap & polythene sleeve for protection of saddle & ferrule,backfilling and shutdown of distribution etc.all as per TAQA Specification.
A39: 4.018 | B39: Tapping in 400 DI Main line | C39: Lump Sum | D39: 1 | E39: 8030.8318 | F39: =$D39*E39 -> 8030.8318
B40: Construct reinforced concrete encased Socket type uPVC DUCTS for the areas under car pass, for the proposed polyethylene house connection pipes, including the supply of uPVC pipe used for protection and all other materials complete with uPVC end cap at each duct end, duct end sealing, bituminous painting of concrete, excavation by hand, dewatering, backfilling and provision of 10 mm dia. pulling rope for installation of polyethylene house connection pipes etc. all as per TAQA Specification and Tender Drawings and as directed by TAQA/ENGINEER :
A41: 4.019 | B41: Reinforce concrete encasement for uPVC pipes for Storm Water Works | C41: Lump Sum | D41: 1 | E41: 18738.608 | F41: =$D41*E41 -> 18738.608
B42: Total Costs for Bill No.4 excluding VAT (AED) | F42: =SUM(F10:F41) -> 566575.37

Sheet Nahel-Bill 05
B5: Bill No.5, INSTRUMENTATION AND CONTROL/ SCADA
A6: Sl.No | B6: Description | C6: UNIT | D6: Quantity (Q) | E6: Unit Rate AED (A) | F6: Total Line Costs Ecxluding VAT B= AED (Q X A)
B7: TANKER CONTROL SYSTEM/WorkStation
B8: CONTROL SYSTEM
A9: 5.001 | B9: Dual system servers including but not limited to, CPU, HDD, keyboard mouse, DVDD, USB drive, software interface devices. | C9: No | D9: 1 | E9: 124949.7 | F9: =$D9*E9 -> 124949.7
A10: 5.002 | B10: Operator workstation including but not limited to, two computers each 21" LCD monitor, CPU, keyboard, mouse, interface devices, 2 GB RAM min., HDD, USB drive, DVDD etc. including one printer. | C10: No | D10: 1 | E10: 40667.798 | F10: =$D10*E10 -> 40667.798
A11: 5.003 | B11: Electronic cabinets including but not limited to, one dual redundant, PLC, communication and power supply modules, interface/signal/alarm etc. modules alongwith suitable communication equipment. | C11: No | D11: 1 | E11: 531639.39 | F11: =$D11*E11 -> 531639.39
A12: 5.004 | B12: Redundant secured communication network, bus and interfaces and other auxiliaries, as required | C12: Lump Sum | D12: 1 | E12: 147036.17 | F12: =$D12*E12 -> 147036.17
A13: 5.005 | B13: Software packages including but not limited to the original license including all application, engineering and HMI software, configuration software etc., as required. | C13: Lump Sum | D13: 1 | E13: 446271.65 | F13: =$D13*E13 -> 446271.65
A14: 5.006 | B14: Field Process Unit, which consists of flow computer with card reader, push buttons for Start / Stop, Emergency push button, lamps for indication, remote I/O module/ RTU | C14: No | D14: 8 | E14: 184262.42 | F14: =$D14*E14 -> 1474099.3
A15: 5.007 | B15: Start / Stop Panel for Manual Tanker Filling Operation as specified | C15: No | D15: 8 | E15: 3588.778 | F15: =$D15*E15 -> 28710.224
